Workbook

Sheet Summary
A1: MEMSマイク ノイズフロア
A2: 容量型MEMSマイクの集中定数等価回路から、雑音源ごとの入力換算ノイズとA特性SNRを計算します。入力は Inputs シートで変更。
A3: ="使用プリセット: "&preset -> 使用プリセット: 標準
A4: 指標 | B4: 値 | C4: 単位
A5: SNR (94 dB SPL, A特性) | B5: =94-B6 -> 66.558434 | C5: dB
A6: 等価入力雑音 N_A | B6: =10*LOG10(SUM(Spectrum!$AU$9:$AU$409)/L_PREF^2) -> 27.441566 | C6: dB(A) SPL
A7: 非加重ノイズ 20 Hz–20 kHz | B7: =10*LOG10(SUM(Spectrum!$BD$9:$BD$409)/L_PREF^2) -> 33.822008 | C7: dB SPL
A8: 感度 @1 kHz | B8: =20*LOG10(SQRT(Spectrum!$R$6)*L_G) -> -38.712291 | C8: dBV/Pa
A9: ゲート点感度 @1 kHz | B9: =20*LOG10(SQRT(Spectrum!$R$6)) -> -46.712291 | C9: dBV/Pa
A10: 共振周波数 | B10: =IF(MAX(Spectrum!$BE$9:$BE$409)>0.5,INDEX(Spectrum!$B$9:$B$409,MATCH(MAX(Spectrum!$BE$9:$BE$409),Spectrum!$BE$9:$BE$409,0)),"なし") -> 29582.168 | C10: Hz
A11: 共振ピーク | B11: =MAX(Spectrum!$BE$9:$BE$409) -> 19.38318 | C11: dB re 1kHz
A12: 低域 −3 dB | B12: =IF(MIN(Spectrum!$BF$9:$BF$409)>100000000,"<10",MIN(Spectrum!$BF$9:$BF$409)) -> 28.250751 | C12: Hz
A13: バイアス / プルイン電圧 | B13: =p_Vbias/L_VPI -> 0.61846658
A14: プルイン判定 | B14: =IF(OR(L_ke>=L_km,p_Vbias>=L_VPI),"崩壊（線形モデル外・値は無効）",IF(B13>0.8,"余裕小","安全")) -> 安全
A16: 雑音源別の寄与
A17: 雑音源 | B17: 領域 | C17: @1 kHz dB SPL/√Hz | D17: 20–20k dB SPL | E17: A特性 dB(A) | F17: A特性 寄与
A18: 音孔 R_p | B18: 音響 | C18: =10*LOG10(Spectrum!S$6/L_PREF^2) -> -24.618015 | D18: =10*LOG10(SUM(Spectrum!$AV$9:$AV$409)/L_PREF^2) -> 20.27818 | E18: =10*LOG10(SUM(Spectrum!$AM$9:$AM$409)/L_PREF^2) -> 17.707587 | F18: =SUM(Spectrum!$AM$9:$AM$409)/SUM(Spectrum!$AU$9:$AU$409) -> 0.10631684
A19: スクイーズ膜 R_sq | B19: 音響 | C19: =10*LOG10(Spectrum!T$6/L_PREF^2) -> -18.889497 | D19: =10*LOG10(SUM(Spectrum!$AW$9:$AW$409)/L_PREF^2) -> 23.413081 | E19: =10*LOG10(SUM(Spectrum!$AN$9:$AN$409)/L_PREF^2) -> 21.722455 | F19: =SUM(Spectrum!$AN$9:$AN$409)/SUM(Spectrum!$AU$9:$AU$409) -> 0.26797165
A20: バックプレート孔 R_h | B20: 音響 | C20: =10*LOG10(Spectrum!U$6/L_PREF^2) -> -20.076548 | D20: =10*LOG10(SUM(Spectrum!$AX$9:$AX$409)/L_PREF^2) -> 22.226031 | E20: =10*LOG10(SUM(Spectrum!$AO$9:$AO$409)/L_PREF^2) -> 20.535404 | F20: =SUM(Spectrum!$AO$9:$AO$409)/SUM(Spectrum!$AU$9:$AU$409) -> 0.20388431
A21: ベント R_v | B21: 音響 | C21: =10*LOG10(Spectrum!V$6/L_PREF^2) -> -17.352005 | D21: =10*LOG10(SUM(Spectrum!$AY$9:$AY$409)/L_PREF^2) -> 29.680706 | E21: =10*LOG10(SUM(Spectrum!$AP$9:$AP$409)/L_PREF^2) -> 16.695516 | F21: =SUM(Spectrum!$AP$9:$AP$409)/SUM(Spectrum!$AU$9:$AU$409) -> 0.084216067
A22: バイアス抵抗 R_b | B22: 電気 | C22: =10*LOG10(Spectrum!W$6/L_PREF^2) -> -20.935401 | D22: =10*LOG10(SUM(Spectrum!$AZ$9:$AZ$409)/L_PREF^2) -> 28.219461 | E22: =10*LOG10(SUM(Spectrum!$AQ$9:$AQ$409)/L_PREF^2) -> 13.267831 | F22: =SUM(Spectrum!$AQ$9:$AQ$409)/SUM(Spectrum!$AU$9:$AU$409) -> 0.038249565
A23: アンプ電圧 e_n | B23: 電気 | C23: =10*LOG10(Spectrum!X$6/L_PREF^2) -> -20.832582 | D23: =10*LOG10(SUM(Spectrum!$BA$9:$BA$409)/L_PREF^2) -> 20.627986 | E23: =10*LOG10(SUM(Spectrum!$AR$9:$AR$409)/L_PREF^2) -> 19.195613 | F23: =SUM(Spectrum!$AR$9:$AR$409)/SUM(Spectrum!$AU$9:$AU$409) -> 0.14976304
A24: アンプ電流 i_n | B24: 電気 | C24: =10*LOG10(Spectrum!Y$6/L_PREF^2) -> -29.121782 | D24: =10*LOG10(SUM(Spectrum!$BB$9:$BB$409)/L_PREF^2) -> 20.03308 | E24: =10*LOG10(SUM(Spectrum!$AS$9:$AS$409)/L_PREF^2) -> 5.0814505 | F24: =SUM(Spectrum!$AS$9:$AS$409)/SUM(Spectrum!$AU$9:$AU$409) -> 0.0058074893
A25: 出力雑音 e_o | B25: 電気 | C25: =10*LOG10(Spectrum!Z$6/L_PREF^2) -> -21.287709 | D25: =10*LOG10(SUM(Spectrum!$BC$9:$BC$409)/L_PREF^2) -> 20.370766 | E25: =10*LOG10(SUM(Spectrum!$AT$9:$AT$409)/L_PREF^2) -> 19.018884 | F25: =SUM(Spectrum!$AT$9:$AT$409)/SUM(Spectrum!$AU$9:$AU$409) -> 0.14379103
A26: 合計 | C26: =10*LOG10(Spectrum!AA$6/L_PREF^2) -> -11.575953 | D26: =B7 -> 33.822008 | E26: =B6 -> 27.441566 | F26: =SUM(F18:F25) -> 1
A27: 音響雑音の割合 | F27: =SUM(F18:F21) -> 0.66238887
A28: 電気雑音の割合 | F28: =SUM(F22:F25) -> 0.33761113

Sheet Inputs
A1: 入力パラメータ
A2: プリセットを選び、変えたい値だけ「上書き」列（黄色）に入力してください。空欄ならプリセット値を使います。青字＝ハードコードされた入力値。
A4: 使用プリセット | C4: 標準 | D4: ← 標準 / 高SNR / 小型 から選択
A6: グループ | B6: パラメータ | C6: 単位 | D6: 標準 | E6: 高SNR | F6: 小型 | G6: 上書き（任意） | H6: 使用値 | I6: SI換算係数 | J6: SI値 | K6: メモ
A7: 環境 | B7: 温度 | C7: °C | D7: 25 | E7: 25 | F7: 25 | H7: =IF(G7<>"",G7,INDEX(D7:F7,MATCH(preset,$D$6:$F$6,0))) -> 25 | I7: 1 | J7: =H7*I7 -> 25 | K7: 周囲温度。kT、空気密度、粘性(Sutherland式)に効く
A8: 音孔・前室 | B8: 音孔 半径 | C8: µm | D8: 125 | E8: 200 | F8: 100 | H8: =IF(G8<>"",G8,INDEX(D8:F8,MATCH(preset,$D$6:$F$6,0))) -> 125 | I8: 1e-06 | J8: =H8*I8 -> 0.000125
A9: 音孔・前室 | B9: 音孔 長さ | C9: µm | D9: 400 | E9: 350 | F9: 300 | H9: =IF(G9<>"",G9,INDEX(D9:F9,MATCH(preset,$D$6:$F$6,0))) -> 400 | I9: 1e-06 | J9: =H9*I9 -> 0.0004 | K9: 基板厚＋パッケージ厚の合計
A10: 音孔・前室 | B10: 前室 容積 | C10: mm³ | D10: 0.15 | E10: 0.25 | F10: 0.08 | H10: =IF(G10<>"",G10,INDEX(D10:F10,MATCH(preset,$D$6:$F$6,0))) -> 0.15 | I10: 1e-09 | J10: =H10*I10 -> 1.5e-10 | K10: 音孔とダイアフラムの間の空間
A11: ダイアフラム | B11: ダイアフラム 半径 | C11: µm | D11: 350 | E11: 500 | F11: 275 | H11: =IF(G11<>"",G11,INDEX(D11:F11,MATCH(preset,$D$6:$F$6,0))) -> 350 | I11: 1e-06 | J11: =H11*I11 -> 0.00035 | K11: ピストン近似の有効半径
A12: ダイアフラム | B12: 膜厚 | C12: µm | D12: 0.6 | E12: 0.6 | F12: 0.6 | H12: =IF(G12<>"",G12,INDEX(D12:F12,MATCH(preset,$D$6:$F$6,0))) -> 0.6 | I12: 1e-06 | J12: =H12*I12 -> 6e-07 | K12: 密度 2330 kg/m³ (poly-Si) を仮定
A13: ダイアフラム | B13: 機械感度 s_m（平均変位） | C13: nm/Pa | D13: 2 | E13: 2.2 | F13: 1.6 | H13: =IF(G13<>"",G13,INDEX(D13:F13,MATCH(preset,$D$6:$F$6,0))) -> 2 | I13: 1e-09 | J13: =H13*I13 -> 2e-09 | K13: 背室なし・バイアスなしでの平均変位/圧力
A14: バックプレート | B14: エアギャップ g0 | C14: µm | D14: 2.5 | E14: 3 | F14: 2 | H14: =IF(G14<>"",G14,INDEX(D14:F14,MATCH(preset,$D$6:$F$6,0))) -> 2.5 | I14: 1e-06 | J14: =H14*I14 -> 2.5e-06
A15: バックプレート | B15: 孔 半径 | C15: µm | D15: 4 | E15: 5 | F15: 3.5 | H15: =IF(G15<>"",G15,INDEX(D15:F15,MATCH(preset,$D$6:$F$6,0))) -> 4 | I15: 1e-06 | J15: =H15*I15 -> 4e-06
A16: バックプレート | B16: 開口率 φ | C16: - | D16: 0.2 | E16: 0.3 | F16: 0.18 | H16: =IF(G16<>"",G16,INDEX(D16:F16,MATCH(preset,$D$6:$F$6,0))) -> 0.2 | I16: 1 | J16: =H16*I16 -> 0.2 | K16: 孔面積/全面積
A17: バックプレート | B17: バックプレート 厚さ | C17: µm | D17: 2 | E17: 2 | F17: 2 | H17: =IF(G17<>"",G17,INDEX(D17:F17,MATCH(preset,$D$6:$F$6,0))) -> 2 | I17: 1e-06 | J17: =H17*I17 -> 2e-06
A18: 背室・ベント | B18: 背室 容積 | C18: mm³ | D18: 1.5 | E18: 4 | F18: 0.4 | H18: =IF(G18<>"",G18,INDEX(D18:F18,MATCH(preset,$D$6:$F$6,0))) -> 1.5 | I18: 1e-09 | J18: =H18*I18 -> 1.5e-09
A19: 背室・ベント | B19: ベント 音響抵抗 R_v | C19: Pa·s/m³ | D19: 500000000000 | E19: 200000000000 | F19: 1500000000000 | H19: =IF(G19<>"",G19,INDEX(D19:F19,MATCH(preset,$D$6:$F$6,0))) -> 500000000000 | I19: 1 | J19: =H19*I19 -> 500000000000 | K19: 低域カットオフ ≈ 1/(2πR_v(C_bv+C_d))
A20: 電気・バイアス | B20: バイアス電圧 V_b | C20: V | D20: 10 | E20: 12 | F20: 8 | H20: =IF(G20<>"",G20,INDEX(D20:F20,MATCH(preset,$D$6:$F$6,0))) -> 10 | I20: 1 | J20: =H20*I20 -> 10 | K20: チャージポンプ出力
A21: 電気・バイアス | B21: 寄生容量 C_p | C21: pF | D21: 0.8 | E21: 0.8 | F21: 0.6 | H21: =IF(G21<>"",G21,INDEX(D21:F21,MATCH(preset,$D$6:$F$6,0))) -> 0.8 | I21: 1e-12 | J21: =H21*I21 -> 8e-13
A22: 電気・バイアス | B22: アンプ入力容量 C_in | C22: pF | D22: 0.3 | E22: 0.3 | F22: 0.3 | H22: =IF(G22<>"",G22,INDEX(D22:F22,MATCH(preset,$D$6:$F$6,0))) -> 0.3 | I22: 1e-12 | J22: =H22*I22 -> 3e-13
A23: 電気・バイアス | B23: バイアス抵抗 R_b | C23: Ω | D23: 1000000000000 | E23: 1000000000000 | F23: 1000000000000 | H23: =IF(G23<>"",G23,INDEX(D23:F23,MATCH(preset,$D$6:$F$6,0))) -> 1000000000000 | I23: 1 | J23: =H23*I23 -> 1000000000000 | K23: ダイオード等で実装される超高抵抗
A24: 前置アンプ・ASIC | B24: 入力電圧雑音 e_n（白色） | C24: nV/√Hz | D24: 8 | E24: 5 | F24: 8 | H24: =IF(G24<>"",G24,INDEX(D24:F24,MATCH(preset,$D$6:$F$6,0))) -> 8 | I24: 1e-09 | J24: =H24*I24 -> 8e-09
A25: 前置アンプ・ASIC | B25: 1/f コーナー f_c | C25: Hz | D25: 100 | E25: 100 | F25: 100 | H25: =IF(G25<>"",G25,INDEX(D25:F25,MATCH(preset,$D$6:$F$6,0))) -> 100 | I25: 1 | J25: =H25*I25 -> 100
A26: 前置アンプ・ASIC | B26: 入力電流雑音 i_n | C26: fA/√Hz | D26: 0.05 | E26: 0.05 | F26: 0.05 | H26: =IF(G26<>"",G26,INDEX(D26:F26,MATCH(preset,$D$6:$F$6,0))) -> 0.05 | I26: 1e-15 | J26: =H26*I26 -> 5e-17
A27: 前置アンプ・ASIC | B27: ASIC ゲイン G | C27: dB | D27: 8 | E27: 8 | F27: 8 | H27: =IF(G27<>"",G27,INDEX(D27:F27,MATCH(preset,$D$6:$F$6,0))) -> 8 | I27: 1 | J27: =H27*I27 -> 8
A28: 前置アンプ・ASIC | B28: 出力換算雑音 e_o（ADC等） | C28: nV/√Hz | D28: 20 | E28: 12 | F28: 20 | H28: =IF(G28<>"",G28,INDEX(D28:F28,MATCH(preset,$D$6:$F$6,0))) -> 20 | I28: 1e-09 | J28: =H28*I28 -> 2e-08 | K28: ゲイン後の白色雑音として扱う
A30: 出典: プリセット値は一般的な市販 MEMS マイク（SNR 60–74 dB 級）の公開寸法・特性に合うよう調整した代表値で、特定製品の値ではありません。

Sheet Lumped
A1: 集中定数（Inputs から自動計算）
A2: すべて数式。編集不要。
A4: 項目 | B4: 名前 | C4: 値 | D4: 単位 | E4: 式・出典
A5: ボルツマン定数 | B5: L_kB | C5: 1.380649e-23 | D5: J/K | E5: CODATA 2018（定数）
A6: 真空の誘電率 | B6: L_eps0 | C6: 8.8541878e-12 | D6: F/m | E6: CODATA 2018（定数）
A7: 大気圧 | B7: L_P0 | C7: 101325 | D7: Pa | E7: 標準大気圧（定数）
A8: 空気の気体定数 | B8: L_Rair | C8: 287.05 | D8: J/(kg·K) | E8: 乾燥空気（定数）
A9: 比熱比 | B9: L_gam | C9: 1.4 | D9: - | E9: 断熱（定数）
A10: ダイアフラム密度 | B10: L_rhoSi | C10: 2330 | D10: kg/m³ | E10: ポリシリコン（仮定）
A11: 基準音圧 | B11: L_PREF | C11: 2e-05 | D11: Pa | E11: 20 µPa（定義）
A12: 絶対温度 | B12: L_Tk | C12: =p_T+273.15 -> 298.15 | D12: K
A13: 4kT | B13: L_kT4 | C13: =4*L_kB*L_Tk -> 1.646562e-20 | D13: J
A14: 空気密度 | B14: L_rho | C14: =L_P0/(L_Rair*L_Tk) -> 1.1839252 | D14: kg/m³ | E14: 理想気体
A15: 粘性係数 | B15: L_mu | C15: =0.00001716*(L_Tk/273.15)^1.5*(273.15+110.4)/(L_Tk+110.4) -> 1.8371494e-05 | D15: Pa·s | E15: Sutherland式
A16: γP0 | B16: L_gP0 | C16: =L_gam*L_P0 -> 141855 | D16: Pa
A17: 平均自由行程 | B17: L_lam | C17: =L_mu/L_P0*SQRT(PI()*L_Rair*L_Tk/2) -> 6.6478923e-08 | D17: m
A18: ダイアフラム面積 A | B18: L_A | C18: =PI()*p_a^2 -> 3.848451e-07 | D18: m²
A19: 静止容量 C0 | B19: L_C0 | C19: =L_eps0*L_A/p_g0 -> 1.3629963e-12 | D19: F
A20: 機械ばね k | B20: L_km | C20: =L_A/p_sm -> 192.42255 | D20: N/m | E20: k = A/s_m
A21: 静電ばね k_e | B21: L_ke | C21: =L_eps0*L_A*p_Vbias^2/p_g0^3 -> 21.807941 | D21: N/m | E21: 線形化した負ばね
A22: プルイン電圧 V_PI | B22: L_VPI | C22: =SQRT(8*L_km*p_g0^3/(27*L_eps0*L_A)) -> 16.169022 | D22: V | E22: 平行平板
A23: 実効ばね k_eff | B23: L_keff | C23: =MAX(L_km-L_ke,L_km*0.001) -> 170.61461 | D23: N/m
A24: 音響コンプライアンス C_d | B24: L_Cd | C24: =L_A^2/L_keff -> 8.6807192e-16 | D24: m³/Pa
A25: ダイアフラム音響質量 M_d | B25: L_Md | C25: =L_rhoSi*p_h/L_A -> 3632.6304 | D25: kg/m⁴ | E25: ピストン近似
A26: クヌーセン数 Kn | B26: L_Kn | C26: =L_lam/p_g0 -> 0.026591569 | D26: -
A27: 実効粘性 μ_eff | B27: L_muEff | C27: =L_mu/(1+9.638*L_Kn^1.159) -> 1.6059451e-05 | D27: Pa·s | E27: Veijola
A28: 孔数 N | B28: L_N | C28: =p_phi*L_A/(PI()*p_rh^2) -> 1531.25 | D28: -
A29: Škvor 係数 B(φ) | B29: L_B | C29: =p_phi/2-p_phi^2/8-LN(p_phi)/4-3/8 -> 0.12235948 | D29: - | E29: Škvor
A30: スクイーズ膜抵抗 R_sq | B30: L_Rsq | C30: =12*L_muEff*L_B/(L_N*PI()*p_g0^3) -> 3.1371375e+08 | D30: Pa·s/m³
A31: 孔流路抵抗 R_h | B31: L_Rh | C31: =8*L_mu*p_tbp/(L_N*PI()*p_rh^4) -> 2.3868686e+08 | D31: Pa·s/m³ | E31: Poiseuille
A32: 孔音響質量 M_h | B32: L_Mh | C32: =L_rho*(p_tbp+1.7*p_rh)/(L_N*PI()*p_rh^2) -> 135.36019 | D32: kg/m⁴ | E32: 端補正 1.7r
A33: 音孔音響質量 M_p | B33: L_Mp | C33: =L_rho*(p_Lp+1.7*p_rp)/(PI()*p_rp^2) -> 14772.719 | D33: kg/m⁴ | E33: 端補正 1.7r
A34: 音孔抵抗 R_p (DC) | B34: L_Rp0 | C34: =8*L_mu*p_Lp/(PI()*p_rp^4) -> 76648652 | D34: Pa·s/m³ | E34: Poiseuille
A35: 音孔抵抗 高域係数 | B35: L_Rp1 | C35: =p_Lp/(PI()*p_rp^3)*SQRT(2*L_rho*L_mu) -> 429961.37 | D35: Pa·s/m³/√(rad/s) | E35: R_hf = 係数×√ω
A36: 前室コンプライアンス C_f | B36: L_Cf | C36: =p_Vf/L_gP0 -> 1.0574178e-15 | D36: m³/Pa
A37: 背室コンプライアンス C_bv | B37: L_Cbv | C37: =p_Vb/L_gP0 -> 1.0574178e-14 | D37: m³/Pa
A38: ゲート総容量 C_tot | B38: L_Ctot | C38: =L_C0+p_Cp+p_Ci -> 2.4629963e-12 | D38: F
A39: ゲイン（倍率） | B39: L_G | C39: =10^(p_G/20) -> 2.5118864 | D39: V/V
A40: ベントアドミタンス 1/R_v | B40: L_Yv | C40: =1/p_Rv -> 2e-12 | D40: m³/(Pa·s)
A41: 変換係数 V_b·C0/(g0·A) | B41: L_Kt | C41: =p_Vbias*L_C0/(p_g0*L_A) -> 14.166701

Sheet Spectrum
A1: 周波数ごとの計算（10 Hz–100 kHz、1デカード100点）
A2: 複素数は Excel の COMPLEX/IM関数の文字列。行6は 1 kHz の基準点、行9以降が周波数グリッド。i=0..300 が積分範囲 20 Hz–20 kHz。
A4: i | B4: f [Hz] | C4: ω [rad/s] | D4: R_p(f) | E4: Z_p | F4: Y_p | G4: Y_f | H4: Y_bv | I4: Z_d | J4: Y_d | K4: S=Yp+Yf+Ybv | L4: det | M4: |H_sig|² | N4: T=Yv·S·Zp/Ybv | O4: |Hd/Hsig|² | P4: |Hv/Hsig|² | Q4: |Z_n|² | R4: |S_g|² [V²/Pa²] | S4: 音孔 R_p [Pa²/Hz] | T4: スクイーズ膜 R_sq [Pa²/Hz] | U4: バックプレート孔 R_h [Pa²/Hz] | V4: ベント R_v [Pa²/Hz] | W4: バイアス抵抗 R_b [Pa²/Hz] | X4: アンプ電圧 e_n [Pa²/Hz] | Y4: アンプ電流 i_n [Pa²/Hz] | Z4: 出力雑音 e_o [Pa²/Hz] | AA4: 合計 [Pa²/Hz] | AB4: 合計 dB SPL/√Hz | AC4: 音孔 R_p dB | AD4: スクイーズ膜 R_sq dB | AE4: バックプレート孔 R_h dB | AF4: ベント R_v dB | AG4: バイアス抵抗 R_b dB | AH4: アンプ電圧 e_n dB | AI4: アンプ電流 i_n dB | AJ4: 出力雑音 e_o dB | AK4: 感度 dB re 1kHz | AL4: A特性 重み² | AM4: ∫A port | AN4: ∫A sq | AO4: ∫A hole | AP4: ∫A vent | AQ4: ∫A rb | AR4: ∫A en | AS4: ∫A in | AT4: ∫A eo | AU4: ∫A 合計 | AV4: ∫Z port | AW4: ∫Z sq | AX4: ∫Z hole | AY4: ∫Z vent | AZ4: ∫Z rb | BA4: ∫Z en | BB4: ∫Z in | BC4: ∫Z eo | BD4: ∫Z 合計 | BE4: 共振探索 | BF4: 低域探索
A6: 1kHz | B6: 1000 | C6: =2*PI()*B6 -> 6283.1853 | D6: =SQRT(L_Rp0^2+L_Rp1^2*C6) -> 83884254 | E6: =COMPLEX(D6,C6*L_Mp) -> 83884254.2231221+92819732.0157811i | F6: =IMDIV(1,E6) -> 5.35930711787611e-09-5.93018862811097e-09i | G6: =COMPLEX(0,C6*L_Cf) -> 6.64395189508257e-12i | H6: =COMPLEX(0,C6*L_Cbv) -> 6.64395189508257e-11i | I6: =COMPLEX(L_Rsq+L_Rh,C6*(L_Md+L_Mh)-1/(C6*L_Cd)) -> 552400610.124532-183319363258.291i | J6: =IMDIV(1,I6) -> 1.64374152239043e-14+5.45491159356062e-12i | K6: =IMSUM(F6,G6,H6) -> 5.35930711787611e-09-5.85710515726506e-09i | L6: =IMSUM(IMPRODUCT(IMSUM(F6,G6),H6),IMPRODUCT(IMSUM(J6,L_Yv),K6)) -> 4.36314156990738e-19+3.73493847368169e-19i | M6: =IMABS(IMDIV(IMPRODUCT(J6,F6,H6),L6))^2 -> 2.5440213e-23 | N6: =IMDIV(IMPRODUCT(L_Yv,K6,E6),H6) -> 0.000184545359290884-0.0298983625259664i | O6: =IMABS(IMSUM(1,IMPRODUCT(E6,G6),N6))^2 -> 0.99999679 | P6: =IMABS(N6)^2 -> 0.00089394614 | Q6: =p_Rb^2/(1+(C6*p_Rb*L_Ctot)^2) -> 4.1755408e+15 | R6: =M6*L_Kt^2*Q6 -> 2.13192e-05 | S6: =L_kT4*D6 -> 1.3812063e-12 | T6: =L_kT4*L_Rsq*O6 -> 5.1654748e-12 | U6: =L_kT4*L_Rh*O6 -> 3.9301145e-12 | V6: =L_kT4*p_Rv*P6 -> 7.3596887e-12 | W6: =L_kT4/p_Rb*Q6/R6 -> 3.2249272e-12 | X6: =p_en^2*(1+p_fc/B6)/R6 -> 3.3021877e-12 | Y6: =p_in^2*Q6/R6 -> 4.8964558e-13 | Z6: =p_eo^2/L_G^2/R6 -> 2.9736448e-12 | AA6: =SUM(S6:Z6) -> 2.782689e-11
A7: (f=1000 Hz は感度・表の基準点。青字は固定値)
A9: -30 | B9: =20*10^(A9/100) -> 10.023745 | C9: =2*PI()*B9 -> 62.981045 | D9: =SQRT(L_Rp0^2+L_Rp1^2*C9) -> 76724566 | E9: =COMPLEX(D9,C9*L_Mp) -> 76724565.7393359+930401.294300282i | F9: =IMDIV(1,E9) -> 1.30317188467098e-08-1.58029282604593e-10i | G9: =COMPLEX(0,C9*L_Cf) -> 6.65972774129821e-14i | H9: =COMPLEX(0,C9*L_Cbv) -> 6.65972774129821e-13i | I9: =COMPLEX(L_Rsq+L_Rh,C9*(L_Md+L_Mh)-1/(C9*L_Cd)) -> 552400610.124532-18290872508422.1i | J9: =IMDIV(1,I9) -> 1.65114534294454e-18+5.4672077487143e-14i | K9: =IMSUM(F9,G9,H9) -> 1.30317188467098e-08-1.5729671255305e-10i | L9: =IMSUM(IMPRODUCT(IMSUM(F9,G9),H9),IMPRODUCT(IMSUM(J9,L_Yv),K9)) -> 2.61772577964949e-20+9.07664740977535e-21i | M9: =IMABS(IMDIV(IMPRODUCT(J9,F9,H9),L9))^2 -> 2.9333033e-28 | N9: =IMDIV(IMPRODUCT(L_Yv,K9,E9),H9) -> 0.000168794044626555-3.00312372295551i | O9: =IMABS(IMSUM(1,IMPRODUCT(E9,G9),N9))^2 -> 10.019059 | P9: =IMABS(N9)^2 -> 9.0187521 | Q9: =p_Rb^2/(1+(C9*p_Rb*L_Ctot)^2) -> 4.1556092e+19 | R9: =M9*L_Kt^2*Q9 -> 2.4464091e-06 | S9: =L_kT4*D9 -> 1.2633175e-12 | T9: =L_kT4*L_Rsq*O9 -> 5.1753362e-11 | U9: =L_kT4*L_Rh*O9 -> 3.9376175e-11 | V9: =L_kT4*p_Rv*P9 -> 7.4249673e-08 | W9: =L_kT4/p_Rb*Q9/R9 -> 2.7969435e-07 | X9: =p_en^2*(1+p_fc/B9)/R9 -> 2.87149e-10 | Y9: =p_in^2*Q9/R9 -> 4.2466417e-08 | Z9: =p_eo^2/L_G^2/R9 -> 2.5913788e-11 | AA9: =SUM(S9:Z9) -> 3.968159e-07 | AB9: =10*LOG10(AA9/L_PREF^2) -> 29.965291 | AC9: =10*LOG10(S9/L_PREF^2) -> -25.005475 | AD9: =10*LOG10(T9/L_PREF^2) -> -8.8812142 | AE9: =10*LOG10(U9/L_PREF^2) -> -10.068265 | AF9: =10*LOG10(V9/L_PREF^2) -> 22.686346 | AG9: =10*LOG10(W9/L_PREF^2) -> 28.446237 | AH9: =10*LOG10(X9/L_PREF^2) -> -1.4395268 | AI9: =10*LOG10(Y9/L_PREF^2) -> 20.259856 | AJ9: =10*LOG10(Z9/L_PREF^2) -> -11.885291 | AK9: =10*LOG10(R9/$R$6) -> -9.4024182 | AL9: =(12194^2*B9^4/((B9^2+20.6^2)*SQRT((B9^2+107.7^2)*(B9^2+737.9^2))*(B9^2+12194^2))*1.2589254)^2 -> 9.2032395e-08 | AM9: 0 | AN9: 0 | AO9: 0 | AP9: 0 | AQ9: 0 | AR9: 0 | AS9: 0 | AT9: 0 | AU9: 0 | AV9: 0 | AW9: 0 | AX9: 0 | AY9: 0 | AZ9: 0 | BA9: 0 | BB9: 0 | BC9: 0 | BD9: 0 | BE9: =IF(B9>2000,AK9,-999) -> -999 | BF9: =IF(AND(B9<1000,AK9>=-3),B9,1000000000) -> 1000000000
A10: -29 | B10: =20*10^(A10/100) -> 10.257228 | C10: =2*PI()*B10 -> 64.448062 | D10: =SQRT(L_Rp0^2+L_Rp1^2*C10) -> 76726333 | E10: =COMPLEX(D10,C10*L_Mp) -> 76726333.0975454+952073.124466422i | F10: =IMDIV(1,E10) -> 1.30313284605585e-08-1.6170168835801e-10i | G10: =COMPLEX(0,C10*L_Cf) -> 6.81485272816819e-14i | H10: =COMPLEX(0,C10*L_Cbv) -> 6.8148527281682e-13i | I10: =COMPLEX(L_Rsq+L_Rh,C10*(L_Md+L_Mh)-1/(C10*L_Cd)) -> 552400610.124532-17874521408057.9i | J10: =IMDIV(1,I10) -> 1.72896142761858e-18+5.59455537978274e-14i | K10: =IMSUM(F10,G10,H10) -> 1.30313284605585e-08-1.60952054557912e-10i | L10: =IMSUM(IMPRODUCT(IMSUM(F10,G10),H10),IMPRODUCT(IMSUM(J10,L_Yv),K10)) -> 2.61818348805963e-20+9.28779893116091e-21i | M10: =IMABS(IMDIV(IMPRODUCT(J10,F10,H10),L10))^2 -> 3.1989744e-28 | N10: =IMDIV(IMPRODUCT(L_Yv,K10,E10),H10) -> 0.000168797932814447-2.93476418693674i | O10: =IMABS(IMSUM(1,IMPRODUCT(E10,G10),N10))^2 -> 9.6131476 | P10: =IMABS(N10)^2 -> 8.6128409 | Q10: =p_Rb^2/(1+(C10*p_Rb*L_Ctot)^2) -> 3.9685834e+19 | R10: =M10*L_Kt^2*Q10 -> 2.5479078e-06 | S10: =L_kT4*D10 -> 1.2633466e-12 | T10: =L_kT4*L_Rsq*O10 -> 4.9656631e-11 | U10: =L_kT4*L_Rh*O10 -> 3.7780892e-11 | V10: =L_kT4*p_Rv*P10 -> 7.0907882e-08 | W10: =L_kT4/p_Rb*Q10/R10 -> 2.5646606e-07 | X10: =p_en^2*(1+p_fc/B10)/R10 -> 2.7000596e-10 | Y10: =p_in^2*Q10/R10 -> 3.893963e-08 | Z10: =p_eo^2/L_G^2/R10 -> 2.4881485e-11 | AA10: =SUM(S10:Z10) -> 3.6669716e-07 | AB10: =10*LOG10(AA10/L_PREF^2) -> 29.622476 | AC10: =10*LOG10(S10/L_PREF^2) -> -25.005375 | AD10: =10*LOG10(T10/L_PREF^2) -> -9.0608274 | AE10: =10*LOG10(U10/L_PREF^2) -> -10.247878 | AF10: =10*LOG10(V10/L_PREF^2) -> 22.486345 | AG10: =10*LOG10(W10/L_PREF^2) -> 28.069699 | AH10: =10*LOG10(X10/L_PREF^2) -> -1.7068665 | AI10: =10*LOG10(Y10/L_PREF^2) -> 19.883318 | AJ10: =10*LOG10(Z10/L_PREF^2) -> -12.061837 | AK10: =10*LOG10(R10/$R$6) -> -9.225872 | AL10: =(12194^2*B10^4/((B10^2+20.6^2)*SQRT((B10^2+107.7^2)*(B10^2+737.9^2))*(B10^2+12194^2))*1.2589254)^2 -> 1.0863245e-07 | AM10: 0 | AN10: 0 | AO10: 0 | AP10: 0 | AQ10: 0 | AR10: 0 | AS10: 0 | AT10: 0 | AU10: 0 | AV10: 0 | AW10: 0 | AX10: 0 | AY10: 0 | AZ10: 0 | BA10: 0 | BB10: 0 | BC10: 0 | BD10: 0 | BE10: =IF(B10>2000,AK10,-999) -> -999 | BF10: =IF(AND(B10<1000,AK10>=-3),B10,1000000000) -> 1000000000
A11: -28 | B11: =20*10^(A11/100) -> 10.496149 | C11: =2*PI()*B11 -> 65.94925 | D11: =SQRT(L_Rp0^2+L_Rp1^2*C11) -> 76728142 | E11: =COMPLEX(D11,C11*L_Mp) -> 76728141.5806732+974249.756405332i | F11: =IMDIV(1,E11) -> 1.3030926864798e-08-1.65459205217646e-10i | G11: =COMPLEX(0,C11*L_Cf) -> 6.97359104015989e-14i | H11: =COMPLEX(0,C11*L_Cbv) -> 6.97359104015989e-13i | I11: =COMPLEX(L_Rsq+L_Rh,C11*(L_Md+L_Mh)-1/(C11*L_Cd)) -> 552400610.124532-17467647615541.4i | J11: =IMDIV(1,I11) -> 1.81044487157516e-18+5.72486931846613e-14i | K11: =IMSUM(F11,G11,H11) -> 1.3030926864798e-08-1.64692110203228e-10i | L11: =IMSUM(IMPRODUCT(IMSUM(F11,G11),H11),IMPRODUCT(IMSUM(J11,L_Yv),K11)) -> 2.61866415815875e-20+9.50385449835556e-21i | M11: =IMABS(IMDIV(IMPRODUCT(J11,F11,H11),L11))^2 -> 3.4879279e-28 | N11: =IMDIV(IMPRODUCT(L_Yv,K11,E11),H11) -> 0.000168801911477403-2.86796070173607i | O11: =IMABS(IMSUM(1,IMPRODUCT(E11,G11),N11))^2 -> 9.2255054 | P11: =IMABS(N11)^2 -> 8.2251986 | Q11: =p_Rb^2/(1+(C11*p_Rb*L_Ctot)^2) -> 3.7899745e+19 | R11: =M11*L_Kt^2*Q11 -> 2.6530242e-06 | S11: =L_kT4*D11 -> 1.2633764e-12 | T11: =L_kT4*L_Rsq*O11 -> 4.7654269e-11 | U11: =L_kT4*L_Rh*O11 -> 3.6257409e-11 | V11: =L_kT4*p_Rv*P11 -> 6.7716497e-08 | W11: =L_kT4/p_Rb*Q11/R11 -> 2.3521941e-07 | X11: =p_en^2*(1+p_fc/B11)/R11 -> 2.539545e-10 | Y11: =p_in^2*Q11/R11 -> 3.5713719e-08 | Z11: =p_eo^2/L_G^2/R11 -> 2.3895646e-11 | AA11: =SUM(S11:Z11) -> 3.3901265e-07 | AB11: =10*LOG10(AA11/L_PREF^2) -> 29.281559 | AC11: =10*LOG10(S11/L_PREF^2) -> -25.005272 | AD11: =10*LOG10(T11/L_PREF^2) -> -9.2395818 | AE11: =10*LOG10(U11/L_PREF^2) -> -10.426632 | AF11: =10*LOG10(V11/L_PREF^2) -> 22.286345 | AG11: =10*LOG10(W11/L_PREF^2) -> 27.694132 | AH11: =10*LOG10(X11/L_PREF^2) -> -1.9730409 | AI11: =10*LOG10(Y11/L_PREF^2) -> 19.507751 | AJ11: =10*LOG10(Z11/L_PREF^2) -> -12.237412 | AK11: =10*LOG10(R11/$R$6) -> -9.0502969 | AL11: =(12194^2*B11^4/((B11^2+20.6^2)*SQRT((B11^2+107.7^2)*(B11^2+737.9^2))*(B11^2+12194^2))*1.2589254)^2 -> 1.2813767e-07 | AM11: 0 | AN11: 0 | AO11: 0 | AP11: 0 | AQ11: 0 | AR11: 0 | AS11: 0 | AT11: 0 | AU11: 0 | AV11: 0 | AW11: 0 | AX11: 0 | AY11: 0 | AZ11: 0 | BA11: 0 | BB11: 0 | BC11: 0 | BD11: 0 | BE11: =IF(B11>2000,AK11,-999) -> -999 | BF11: =IF(AND(B11<1000,AK11>=-3),B11,1000000000) -> 1000000000
A12: -27 | B12: =20*10^(A12/100) -> 10.740636 | C12: =2*PI()*B12 -> 67.485406 | D12: =SQRT(L_Rp0^2+L_Rp1^2*C12) -> 76729992 | E12: =COMPLEX(D12,C12*L_Mp) -> 76729992.1446587+996942.948460808i | F12: =IMDIV(1,E12) -> 1.30305136991533e-08-1.69303793524461e-10i | G12: =COMPLEX(0,C12*L_Cf) -> 7.13602684242747e-14i | H12: =COMPLEX(0,C12*L_Cbv) -> 7.13602684242747e-13i | I12: =COMPLEX(L_Rsq+L_Rh,C12*(L_Md+L_Mh)-1/(C12*L_Cd)) -> 552400610.124532-17070035401002.4i | J12: =IMDIV(1,I12) -> 1.89576851215139e-18+5.85821865896103e-14i | K12: =IMSUM(F12,G12,H12) -> 1.30305136991533e-08-1.68518830571794e-10i | L12: =IMSUM(IMPRODUCT(IMSUM(F12,G12),H12),IMPRODUCT(IMSUM(J12,L_Yv),K12)) -> 2.6191689021353e-20+9.72492755704367e-21i | M12: =IMABS(IMDIV(IMPRODUCT(J12,F12,H12),L12))^2 -> 3.8021018e-28 | N12: =IMDIV(IMPRODUCT(L_Yv,K12,E12),H12) -> 0.00016880598271833-2.80267784726143i | O12: =IMABS(IMSUM(1,IMPRODUCT(E12,G12),N12))^2 -> 8.8553099 | P12: =IMABS(N12)^2 -> 7.8550031 | Q12: =p_Rb^2/(1+(C12*p_Rb*L_Ctot)^2) -> 3.6194037e+19 | R12: =M12*L_Kt^2*Q12 -> 2.761838e-06 | S12: =L_kT4*D12 -> 1.2634069e-12 | T12: =L_kT4*L_Rsq*O12 -> 4.5742027e-11 | U12: =L_kT4*L_Rh*O12 -> 3.4802494e-11 | V12: =L_kT4*p_Rv*P12 -> 6.4668748e-08 | W12: =L_kT4/p_Rb*Q12/R12 -> 2.1578285e-07 | X12: =p_en^2*(1+p_fc/B12)/R12 -> 2.3892346e-10 | Y12: =p_in^2*Q12/R12 -> 3.2762636e-08 | Z12: =p_eo^2/L_G^2/R12 -> 2.2954181e-11 | AA12: =SUM(S12:Z12) -> 3.1355792e-07 | AB12: =10*LOG10(AA12/L_PREF^2) -> 28.942578 | AC12: =10*LOG10(S12/L_PREF^2) -> -25.005167 | AD12: =10*LOG10(T12/L_PREF^2) -> -9.4174458 | AE12: =10*LOG10(U12/L_PREF^2) -> -10.604496 | AF12: =10*LOG10(V12/L_PREF^2) -> 22.086345 | AG12: =10*LOG10(W12/L_PREF^2) -> 27.319569 | AH12: =10*LOG10(X12/L_PREF^2) -> -2.238012 | AI12: =10*LOG10(Y12/L_PREF^2) -> 19.133188 | AJ12: =10*LOG10(Z12/L_PREF^2) -> -12.411982 | AK12: =10*LOG10(R12/$R$6) -> -8.8757271 | AL12: =(12194^2*B12^4/((B12^2+20.6^2)*SQRT((B12^2+107.7^2)*(B12^2+737.9^2))*(B12^2+12194^2))*1.2589254)^2 -> 1.5103717e-07 | AM12: 0 | AN12: 0 | AO12: 0 | AP12: 0 | AQ12: 0 | AR12: 0 | AS12: 0 | AT12: 0 | AU12: 0 | AV12: 0 | AW12: 0 | AX12: 0 | AY12: 0 | AZ12: 0 | BA12: 0 | BB12: 0 | BC12: 0 | BD12: 0 | BE12: =IF(B12>2000,AK12,-999) -> -999 | BF12: =IF(AND(B12<1000,AK12>=-3),B12,1000000000) -> 1000000000
A13: -26 | B13: =20*10^(A13/100) -> 10.990817 | C13: =2*PI()*B13 -> 69.057343 | D13: =SQRT(L_Rp0^2+L_Rp1^2*C13) -> 76731886 | E13: =COMPLEX(D13,C13*L_Mp) -> 76731885.7676149+1020164.73286366i | F13: =IMDIV(1,E13) -> 1.30300885903264e-08-1.73237458104418e-10i | G13: =COMPLEX(0,C13*L_Cf) -> 7.30224626058339e-14i | H13: =COMPLEX(0,C13*L_Cbv) -> 7.30224626058339e-13i | I13: =COMPLEX(L_Rsq+L_Rh,C13*(L_Md+L_Mh)-1/(C13*L_Cd)) -> 552400610.124532-16681473945181.7i | J13: =IMDIV(1,I13) -> 1.98511333225902e-18+5.99467410487587e-14i | K13: =IMSUM(F13,G13,H13) -> 1.30300885903264e-08-1.72434211015754e-10i | L13: =IMSUM(IMPRODUCT(IMSUM(F13,G13),H13),IMPRODUCT(IMSUM(J13,L_Yv),K13)) -> 2.61969888511142e-20+9.95113415061185e-21i | M13: =IMABS(IMDIV(IMPRODUCT(J13,F13,H13),L13))^2 -> 4.1435823e-28 | N13: =IMDIV(IMPRODUCT(L_Yv,K13,E13),H13) -> 0.000168810148688669-2.73888100967921i | O13: =IMABS(IMSUM(1,IMPRODUCT(E13,G13),N13))^2 -> 8.501776 | P13: =IMABS(N13)^2 -> 7.5014692 | Q13: =p_Rb^2/(1+(C13*p_Rb*L_Ctot)^2) -> 3.4565093e+19 | R13: =M13*L_Kt^2*Q13 -> 2.874426e-06 | S13: =L_kT4*D13 -> 1.2634381e-12 | T13: =L_kT4*L_Rsq*O13 -> 4.3915851e-11 | U13: =L_kT4*L_Rh*O13 -> 3.3413061e-11 | V13: =L_kT4*p_Rv*P13 -> 6.1758171e-08 | W13: =L_kT4/p_Rb*Q13/R13 -> 1.9799977e-07 | X13: =p_en^2*(1+p_fc/B13)/R13 -> 2.2484638e-10 | Y13: =p_in^2*Q13/R13 -> 3.0062605e-08 | Z13: =p_eo^2/L_G^2/R13 -> 2.2055091e-11 | AA13: =SUM(S13:Z13) -> 2.9014604e-07 | AB13: =10*LOG10(AA13/L_PREF^2) -> 28.605567 | AC13: =10*LOG10(S13/L_PREF^2) -> -25.00506 | AD13: =10*LOG10(T13/L_PREF^2) -> -9.5943869 | AE13: =10*LOG10(U13/L_PREF^2) -> -10.781437 | AF13: =10*LOG10(V13/L_PREF^2) -> 21.886344 | AG13: =10*LOG10(W13/L_PREF^2) -> 26.946047 | AH13: =10*LOG10(X13/L_PREF^2) -> -2.5017409 | AI13: =10*LOG10(Y13/L_PREF^2) -> 18.759666 | AJ13: =10*LOG10(Z13/L_PREF^2) -> -12.585511 | AK13: =10*LOG10(R13/$R$6) -> -8.7021977 | AL13: =(12194^2*B13^4/((B13^2+20.6^2)*SQRT((B13^2+107.7^2)*(B13^2+737.9^2))*(B13^2+12194^2))*1.2589254)^2 -> 1.7789844e-07 | AM13: 0 | AN13: 0 | AO13: 0 | AP13: 0 | AQ13: 0 | AR13: 0 | AS13: 0 | AT13: 0 | AU13: 0 | AV13: 0 | AW13: 0 | AX13: 0 | AY13: 0 | AZ13: 0 | BA13: 0 | BB13: 0 | BC13: 0 | BD13: 0 | BE13: =IF(B13>2000,AK13,-999) -> -999 | BF13: =IF(AND(B13<1000,AK13>=-3),B13,1000000000) -> 1000000000
A14: -25 | B14: =20*10^(A14/100) -> 11.246827 | C14: =2*PI()*B14 -> 70.665895 | D14: =SQRT(L_Rp0^2+L_Rp1^2*C14) -> 76733823 | E14: =COMPLEX(D14,C14*L_Mp) -> 76733823.45034+1043927.42211135i | F14: =IMDIV(1,E14) -> 1.30296511514791e-08-1.77262249239758e-10i | G14: =COMPLEX(0,C14*L_Cf) -> 7.47233742636333e-14i | H14: =COMPLEX(0,C14*L_Cbv) -> 7.47233742636333e-13i | I14: =COMPLEX(L_Rsq+L_Rh,C14*(L_Md+L_Mh)-1/(C14*L_Cd)) -> 552400610.124532-16301757227652i | J14: =IMDIV(1,I14) -> 2.07866884427368e-18+6.13430800671895e-14i | K14: =IMSUM(F14,G14,H14) -> 1.30296511514791e-08-1.76440292122858e-10i | L14: =IMSUM(IMPRODUCT(IMSUM(F14,G14),H14),IMPRODUCT(IMSUM(J14,L_Yv),K14)) -> 2.62025532763557e-20+1.01825929779916e-20i | M14: =IMABS(IMDIV(IMPRODUCT(J14,F14,H14),L14))^2 -> 4.5146138e-28 | N14: =IMDIV(IMPRODUCT(L_Yv,K14,E14),H14) -> 0.000168814411590761-2.67653636306174i | O14: =IMABS(IMSUM(1,IMPRODUCT(E14,G14),N14))^2 -> 8.1641537 | P14: =IMABS(N14)^2 -> 7.1638469 | Q14: =p_Rb^2/(1+(C14*p_Rb*L_Ctot)^2) -> 3.3009459e+19 | R14: =M14*L_Kt^2*Q14 -> 2.9908625e-06 | S14: =L_kT4*D14 -> 1.26347e-12 | T14: =L_kT4*L_Rsq*O14 -> 4.2171866e-11 | U14: =L_kT4*L_Rh*O14 -> 3.2086162e-11 | V14: =L_kT4*p_Rv*P14 -> 5.8978591e-08 | W14: =L_kT4/p_Rb*Q14/R14 -> 1.8172725e-07 | X14: =p_en^2*(1+p_fc/B14)/R14 -> 2.1166116e-10 | Y14: =p_in^2*Q14/R14 -> 2.7591923e-08 | Z14: =p_eo^2/L_G^2/R14 -> 2.119647e-11 | AA14: =SUM(S14:Z14) -> 2.6860614e-07 | AB14: =10*LOG10(AA14/L_PREF^2) -> 28.270559 | AC14: =10*LOG10(S14/L_PREF^2) -> -25.004951 | AD14: =10*LOG10(T14/L_PREF^2) -> -9.7703718 | AE14: =10*LOG10(U14/L_PREF^2) -> -10.957422 | AF14: =10*LOG10(V14/L_PREF^2) -> 21.686344 | AG14: =10*LOG10(W14/L_PREF^2) -> 26.573601 | AH14: =10*LOG10(X14/L_PREF^2) -> -2.7641883 | AI14: =10*LOG10(Y14/L_PREF^2) -> 18.38722 | AJ14: =10*LOG10(Z14/L_PREF^2) -> -12.757964 | AK14: =10*LOG10(R14/$R$6) -> -8.5297446 | AL14: =(12194^2*B14^4/((B14^2+20.6^2)*SQRT((B14^2+107.7^2)*(B14^2+737.9^2))*(B14^2+12194^2))*1.2589254)^2 -> 2.0937898e-07 | AM14: 0 | AN14: 0 | AO14: 0 | AP14: 0 | AQ14: 0 | AR14: 0 | AS14: 0 | AT14: 0 | AU14: 0 | AV14: 0 | AW14: 0 | AX14: 0 | AY14: 0 | AZ14: 0 | BA14: 0 | BB14: 0 | BC14: 0 | BD14: 0 | BE14: =IF(B14>2000,AK14,-999) -> -999 | BF14: =IF(AND(B14<1000,AK14>=-3),B14,1000000000) -> 1000000000
A15: -24 | B15: =20*10^(A15/100) -> 11.508799 | C15: =2*PI()*B15 -> 72.311915 | D15: =SQRT(L_Rp0^2+L_Rp1^2*C15) -> 76735806 | E15: =COMPLEX(D15,C15*L_Mp) -> 76735806.216842+1068243.61549626i | F15: =IMDIV(1,E15) -> 1.30292009816915e-08-1.81380263659167e-10i | G15: =COMPLEX(0,C15*L_Cf) -> 7.6463905243548e-14i | H15: =COMPLEX(0,C15*L_Cbv) -> 7.6463905243548e-13i | I15: =COMPLEX(L_Rsq+L_Rh,C15*(L_Md+L_Mh)-1/(C15*L_Cd)) -> 552400610.124532-15930683917583.8i | J15: =IMDIV(1,I15) -> 2.17663349201621e-18+6.27719440025959e-14i | K15: =IMSUM(F15,G15,H15) -> 1.30292009816915e-08-1.80539160701488e-10i | L15: =IMSUM(IMPRODUCT(IMSUM(F15,G15),H15),IMPRODUCT(IMSUM(J15,L_Yv),K15)) -> 2.62083950829108e-20+1.04194254526828e-20i | M15: =IMABS(IMDIV(IMPRODUCT(J15,F15,H15),L15))^2 -> 4.9176091e-28 | N15: =IMDIV(IMPRODUCT(L_Yv,K15,E15),H15) -> 0.00016881877367705-2.61561085145207i | O15: =IMABS(IMSUM(1,IMPRODUCT(E15,G15),N15))^2 -> 7.8417269 | P15: =IMABS(N15)^2 -> 6.8414202 | Q15: =p_Rb^2/(1+(C15*p_Rb*L_Ctot)^2) -> 3.1523836e+19 | R15: =M15*L_Kt^2*Q15 -> 3.1112183e-06 | S15: =L_kT4*D15 -> 1.2635026e-12 | T15: =L_kT4*L_Rsq*O15 -> 4.0506373e-11 | U15: =L_kT4*L_Rh*O15 -> 3.0818984e-11 | V15: =L_kT4*p_Rv*P15 -> 5.6324112e-08 | W15: =L_kT4/p_Rb*Q15/R15 -> 1.6683481e-07 | X15: =p_en^2*(1+p_fc/B15)/R15 -> 1.9930979e-10 | Y15: =p_in^2*Q15/R15 -> 2.5330781e-08 | Z15: =p_eo^2/L_G^2/R15 -> 2.0376496e-11 | AA15: =SUM(S15:Z15) -> 2.4878197e-07 | AB15: =10*LOG10(AA15/L_PREF^2) -> 27.937589 | AC15: =10*LOG10(S15/L_PREF^2) -> -25.004838 | AD15: =10*LOG10(T15/L_PREF^2) -> -9.9453663 | AE15: =10*LOG10(U15/L_PREF^2) -> -11.132417 | AF15: =10*LOG10(V15/L_PREF^2) -> 21.486344 | AG15: =10*LOG10(W15/L_PREF^2) -> 26.202267 | AH15: =10*LOG10(X15/L_PREF^2) -> -3.0253136 | AI15: =10*LOG10(Y15/L_PREF^2) -> 18.015886 | AJ15: =10*LOG10(Z15/L_PREF^2) -> -12.929305 | AK15: =10*LOG10(R15/$R$6) -> -8.3584042 | AL15: =(12194^2*B15^4/((B15^2+20.6^2)*SQRT((B15^2+107.7^2)*(B15^2+737.9^2))*(B15^2+12194^2))*1.2589254)^2 -> 2.4623974e-07 | AM15: 0 | AN15: 0 | AO15: 0 | AP15: 0 | AQ15: 0 | AR15: 0 | AS15: 0 | AT15: 0 | AU15: 0 | AV15: 0 | AW15: 0 | AX15: 0 | AY15: 0 | AZ15: 0 | BA15: 0 | BB15: 0 | BC15: 0 | BD15: 0 | BE15: =IF(B15>2000,AK15,-999) -> -999 | BF15: =IF(AND(B15<1000,AK15>=-3),B15,1000000000) -> 1000000000
A16: -23 | B16: =20*10^(A16/100) -> 11.776873 | C16: =2*PI()*B16 -> 73.996276 | D16: =SQRT(L_Rp0^2+L_Rp1^2*C16) -> 76737835 | E16: =COMPLEX(D16,C16*L_Mp) -> 76737835.1148738+1093126.20578597i | F16: =IMDIV(1,E16) -> 1.30287376654002e-08-1.85593645547074e-10i | G16: =COMPLEX(0,C16*L_Cf) -> 7.82449783981423e-14i | H16: =COMPLEX(0,C16*L_Cbv) -> 7.82449783981423e-13i | I16: =COMPLEX(L_Rsq+L_Rh,C16*(L_Md+L_Mh)-1/(C16*L_Cd)) -> 552400610.124532-15568057266996.1i | J16: =IMDIV(1,I16) -> 2.27921507167915e-18+6.42340904578335e-14i | K16: =IMSUM(F16,G16,H16) -> 1.30287376654002e-08-1.84732950784694e-10i | L16: =IMSUM(IMPRODUCT(IMSUM(F16,G16),H16),IMPRODUCT(IMSUM(J16,L_Yv),K16)) -> 2.62145276642671e-20+1.06617557629782e-20i | M16: =IMABS(IMDIV(IMPRODUCT(J16,F16,H16),L16))^2 -> 5.3551599e-28 | N16: =IMDIV(IMPRODUCT(L_Yv,K16,E16),H16) -> 0.000168823237252761-2.55607217133756i | O16: =IMABS(IMSUM(1,IMPRODUCT(E16,G16),N16))^2 -> 7.5338118 | P16: =IMABS(N16)^2 -> 6.533505 | Q16: =p_Rb^2/(1+(C16*p_Rb*L_Ctot)^2) -> 3.0105072e+19 | R16: =M16*L_Kt^2*Q16 -> 3.2355606e-06 | S16: =L_kT4*D16 -> 1.263536e-12 | T16: =L_kT4*L_Rsq*O16 -> 3.891584e-11 | U16: =L_kT4*L_Rh*O16 -> 2.9608838e-11 | V16: =L_kT4*p_Rv*P16 -> 5.3789105e-08 | W16: =L_kT4/p_Rb*Q16/R16 -> 1.5320334e-07 | X16: =p_en^2*(1+p_fc/B16)/R16 -> 1.8773809e-10 | Y16: =p_in^2*Q16/R16 -> 2.3261094e-08 | Z16: =p_eo^2/L_G^2/R16 -> 1.9593429e-11 | AA16: =SUM(S16:Z16) -> 2.3053065e-07 | AB16: =10*LOG10(AA16/L_PREF^2) -> 27.606687 | AC16: =10*LOG10(S16/L_PREF^2) -> -25.004724 | AD16: =10*LOG10(T16/L_PREF^2) -> -10.119336 | AE16: =10*LOG10(U16/L_PREF^2) -> -11.306386 | AF16: =10*LOG10(V16/L_PREF^2) -> 21.286343 | AG16: =10*LOG10(W16/L_PREF^2) -> 25.832082 | AH16: =10*LOG10(X16/L_PREF^2) -> -3.2850759 | AI16: =10*LOG10(Y16/L_PREF^2) -> 17.645702 | AJ16: =10*LOG10(Z16/L_PREF^2) -> -13.099495 | AK16: =10*LOG10(R16/$R$6) -> -8.1882137 | AL16: =(12194^2*B16^4/((B16^2+20.6^2)*SQRT((B16^2+107.7^2)*(B16^2+737.9^2))*(B16^2+12194^2))*1.2589254)^2 -> 2.8936016e-07 | AM16: 0 | AN16: 0 | AO16: 0 | AP16: 0 | AQ16: 0 | AR16: 0 | AS16: 0 | AT16: 0 | AU16: 0 | AV16: 0 | AW16: 0 | AX16: 0 | AY16: 0 | AZ16: 0 | BA16: 0 | BB16: 0 | BC16: 0 | BD16: 0 | BE16: =IF(B16>2000,AK16,-999) -> -999 | BF16: =IF(AND(B16<1000,AK16>=-3),B16,1000000000) -> 1000000000
A17: -22 | B17: =20*10^(A17/100) -> 12.051192 | C17: =2*PI()*B17 -> 75.719871 | D17: =SQRT(L_Rp0^2+L_Rp1^2*C17) -> 76739911 | E17: =COMPLEX(D17,C17*L_Mp) -> 76739911.2164817+1118588.38605924i | F17: =IMDIV(1,E17) -> 1.30282607718101e-08-1.89904587572263e-10i | G17: =COMPLEX(0,C17*L_Cf) -> 8.0067538075978e-14i | H17: =COMPLEX(0,C17*L_Cbv) -> 8.0067538075978e-13i | I17: =COMPLEX(L_Rsq+L_Rh,C17*(L_Md+L_Mh)-1/(C17*L_Cd)) -> 552400610.124532-15213685006439.1i | J17: =IMDIV(1,I17) -> 2.38663117259036e-18+6.57302946826084e-14i | K17: =IMSUM(F17,G17,H17) -> 1.30282607718101e-08-1.89023844653427e-10i | L17: =IMSUM(IMPRODUCT(IMSUM(F17,G17),H17),IMPRODUCT(IMSUM(J17,L_Yv),K17)) -> 2.62209650501405e-20+1.09097109334027e-20i | M17: =IMABS(IMDIV(IMPRODUCT(J17,F17,H17),L17))^2 -> 5.8300482e-28 | N17: =IMDIV(IMPRODUCT(L_Yv,K17,E17),H17) -> 0.000168827804676137-2.49788875452189i | O17: =IMABS(IMSUM(1,IMPRODUCT(E17,G17),N17))^2 -> 7.239755 | P17: =IMABS(N17)^2 -> 6.2394483 | Q17: =p_Rb^2/(1+(C17*p_Rb*L_Ctot)^2) -> 2.875016e+19 | R17: =M17*L_Kt^2*Q17 -> 3.3639523e-06 | S17: =L_kT4*D17 -> 1.2635702e-12 | T17: =L_kT4*L_Rsq*O17 -> 3.7396892e-11 | U17: =L_kT4*L_Rh*O17 -> 2.8453158e-11 | V17: =L_kT4*p_Rv*P17 -> 5.1368192e-08 | W17: =L_kT4/p_Rb*Q17/R17 -> 1.4072411e-07 | X17: =p_en^2*(1+p_fc/B17)/R17 -> 1.7689543e-10 | Y17: =p_in^2*Q17/R17 -> 2.1366355e-08 | Z17: =p_eo^2/L_G^2/R17 -> 1.8845608e-11 | AA17: =SUM(S17:Z17) -> 2.1372151e-07 | AB17: =10*LOG10(AA17/L_PREF^2) -> 27.277882 | AC17: =10*LOG10(S17/L_PREF^2) -> -25.004606 | AD17: =10*LOG10(T17/L_PREF^2) -> -10.292245 | AE17: =10*LOG10(U17/L_PREF^2) -> -11.479295 | AF17: =10*LOG10(V17/L_PREF^2) -> 21.086343 | AG17: =10*LOG10(W17/L_PREF^2) -> 25.463085 | AH17: =10*LOG10(X17/L_PREF^2) -> -3.5434337 | AI17: =10*LOG10(Y17/L_PREF^2) -> 17.276704 | AJ17: =10*LOG10(Z17/L_PREF^2) -> -13.268498 | AK17: =10*LOG10(R17/$R$6) -> -8.0192107 | AL17: =(12194^2*B17^4/((B17^2+20.6^2)*SQRT((B17^2+107.7^2)*(B17^2+737.9^2))*(B17^2+12194^2))*1.2589254)^2 -> 3.397554e-07 | AM17: 0 | AN17: 0 | AO17: 0 | AP17: 0 | AQ17: 0 | AR17: 0 | AS17: 0 | AT17: 0 | AU17: 0 | AV17: 0 | AW17: 0 | AX17: 0 | AY17: 0 | AZ17: 0 | BA17: 0 | BB17: 0 | BC17: 0 | BD17: 0 | BE17: =IF(B17>2000,AK17,-999) -> -999 | BF17: =IF(AND(B17<1000,AK17>=-3),B17,1000000000) -> 1000000000
A18: -21 | B18: =20*10^(A18/100) -> 12.3319 | C18: =2*PI()*B18 -> 77.483613 | D18: =SQRT(L_Rp0^2+L_Rp1^2*C18) -> 76742036 | E18: =COMPLEX(D18,C18*L_Mp) -> 76742035.6185661+1144643.65670106i | F18: =IMDIV(1,E18) -> 1.30277698542834e-08-1.9431533193601e-10i | G18: =COMPLEX(0,C18*L_Cf) -> 8.19325506223207e-14i | H18: =COMPLEX(0,C18*L_Cbv) -> 8.19325506223207e-13i | I18: =COMPLEX(L_Rsq+L_Rh,C18*(L_Md+L_Mh)-1/(C18*L_Cd)) -> 552400610.124532-14867379243049.4i | J18: =IMDIV(1,I18) -> 2.49910963874986e-18+6.72613499845305e-14i | K18: =IMSUM(F18,G18,H18) -> 1.30277698542834e-08-1.93414073879164e-10i | L18: =IMSUM(IMPRODUCT(IMSUM(F18,G18),H18),IMPRODUCT(IMSUM(J18,L_Yv),K18)) -> 2.62277219363841e-20+1.11634208873858e-20i | M18: =IMABS(IMDIV(IMPRODUCT(J18,F18,H18),L18))^2 -> 6.3452581e-28 | N18: =IMDIV(IMPRODUCT(L_Yv,K18,E18),H18) -> 0.00016883247836097-2.44102975138736i | O18: =IMABS(IMSUM(1,IMPRODUCT(E18,G18),N18))^2 -> 6.9589331 | P18: =IMABS(N18)^2 -> 5.9586263 | Q18: =p_Rb^2/(1+(C18*p_Rb*L_Ctot)^2) -> 2.7456225e+19 | R18: =M18*L_Kt^2*Q18 -> 3.4964517e-06 | S18: =L_kT4*D18 -> 1.2636052e-12 | T18: =L_kT4*L_Rsq*O18 -> 3.5946309e-11 | U18: =L_kT4*L_Rh*O18 -> 2.7349492e-11 | V18: =L_kT4*p_Rv*P18 -> 4.9056238e-08 | W18: =L_kT4/p_Rb*Q18/R18 -> 1.2929787e-07 | X18: =p_en^2*(1+p_fc/B18)/R18 -> 1.6673453e-10 | Y18: =p_in^2*Q18/R18 -> 1.9631491e-08 | Z18: =p_eo^2/L_G^2/R18 -> 1.8131446e-11 | AA18: =SUM(S18:Z18) -> 1.9823502e-07 | AB18: =10*LOG10(AA18/L_PREF^2) -> 26.951204 | AC18: =10*LOG10(S18/L_PREF^2) -> -25.004486 | AD18: =10*LOG10(T18/L_PREF^2) -> -10.464057 | AE18: =10*LOG10(U18/L_PREF^2) -> -11.651107 | AF18: =10*LOG10(V18/L_PREF^2) -> 20.886342 | AG18: =10*LOG10(W18/L_PREF^2) -> 25.095314 | AH18: =10*LOG10(X18/L_PREF^2) -> -3.8003445 | AI18: =10*LOG10(Y18/L_PREF^2) -> 16.908933 | AJ18: =10*LOG10(Z18/L_PREF^2) -> -13.436275 | AK18: =10*LOG10(R18/$R$6) -> -7.8514337 | AL18: =(12194^2*B18^4/((B18^2+20.6^2)*SQRT((B18^2+107.7^2)*(B18^2+737.9^2))*(B18^2+12194^2))*1.2589254)^2 -> 3.9859569e-07 | AM18: 0 | AN18: 0 | AO18: 0 | AP18: 0 | AQ18: 0 | AR18: 0 | AS18: 0 | AT18: 0 | AU18: 0 | AV18: 0 | AW18: 0 | AX18: 0 | AY18: 0 | AZ18: 0 | BA18: 0 | BB18: 0 | BC18: 0 | BD18: 0 | BE18: =IF(B18>2000,AK18,-999) -> -999 | BF18: =IF(AND(B18<1000,AK18>=-3),B18,1000000000) -> 1000000000
A19: -20 | B19: =20*10^(A19/100) -> 12.619147 | C19: =2*PI()*B19 -> 79.288438 | D19: =SQRT(L_Rp0^2+L_Rp1^2*C19) -> 76744209 | E19: =COMPLEX(D19,C19*L_Mp) -> 76744209.4434543+1171305.83256081i | F19: =IMDIV(1,E19) -> 1.30272644497009e-08-1.98828171439953e-10i | G19: =COMPLEX(0,C19*L_Cf) -> 8.38410048915089e-14i | H19: =COMPLEX(0,C19*L_Cbv) -> 8.38410048915089e-13i | I19: =COMPLEX(L_Rsq+L_Rh,C19*(L_Md+L_Mh)-1/(C19*L_Cd)) -> 552400610.124532-14528956360927.3i | J19: =IMDIV(1,I19) -> 2.6168890521177e-18+6.88280681497349e-14i | K19: =IMSUM(F19,G19,H19) -> 1.30272644497009e-08-1.97905920386146e-10i | L19: =IMSUM(IMPRODUCT(IMSUM(F19,G19),H19),IMPRODUCT(IMSUM(J19,L_Yv),K19)) -> 2.62348137162848e-20+1.1423018511182e-20i | M19: =IMABS(IMDIV(IMPRODUCT(J19,F19,H19),L19))^2 -> 6.9039873e-28 | N19: =IMDIV(IMPRODUCT(L_Yv,K19,E19),H19) -> 0.000168837260775577-2.38546501453786i | O19: =IMABS(IMSUM(1,IMPRODUCT(E19,G19),N19))^2 -> 6.6907501 | P19: =IMABS(N19)^2 -> 5.6904434 | Q19: =p_Rb^2/(1+(C19*p_Rb*L_Ctot)^2) -> 2.6220524e+19 | R19: =M19*L_Kt^2*Q19 -> 3.6331119e-06 | S19: =L_kT4*D19 -> 1.263641e-12 | T19: =L_kT4*L_Rsq*O19 -> 3.4561012e-11 | U19: =L_kT4*L_Rh*O19 -> 2.6295499e-11 | V19: =L_kT4*p_Rv*P19 -> 4.6848339e-08 | W19: =L_kT4/p_Rb*Q19/R19 -> 1.1883399e-07 | X19: =p_en^2*(1+p_fc/B19)/R19 -> 1.5721119e-10 | Y19: =p_in^2*Q19/R19 -> 1.8042744e-08 | Z19: =p_eo^2/L_G^2/R19 -> 1.7449429e-11 | AA19: =SUM(S19:Z19) -> 1.8396185e-07 | AB19: =10*LOG10(AA19/L_PREF^2) -> 26.626678 | AC19: =10*LOG10(S19/L_PREF^2) -> -25.004363 | AD19: =10*LOG10(T19/L_PREF^2) -> -10.634735 | AE19: =10*LOG10(U19/L_PREF^2) -> -11.821786 | AF19: =10*LOG10(V19/L_PREF^2) -> 20.686342 | AG19: =10*LOG10(W19/L_PREF^2) -> 24.728807 | AH19: =10*LOG10(X19/L_PREF^2) -> -4.0557655 | AI19: =10*LOG10(Y19/L_PREF^2) -> 16.542426 | AJ19: =10*LOG10(Z19/L_PREF^2) -> -13.602788 | AK19: =10*LOG10(R19/$R$6) -> -7.6849214 | AL19: =(12194^2*B19^4/((B19^2+20.6^2)*SQRT((B19^2+107.7^2)*(B19^2+737.9^2))*(B19^2+12194^2))*1.2589254)^2 -> 4.6722819e-07 | AM19: 0 | AN19: 0 | AO19: 0 | AP19: 0 | AQ19: 0 | AR19: 0 | AS19: 0 | AT19: 0 | AU19: 0 | AV19: 0 | AW19: 0 | AX19: 0 | AY19: 0 | AZ19: 0 | BA19: 0 | BB19: 0 | BC19: 0 | BD19: 0 | BE19: =IF(B19>2000,AK19,-999) -> -999 | BF19: =IF(AND(B19<1000,AK19>=-3),B19,1000000000) -> 1000000000
A20: -19 | B20: =20*10^(A20/100) -> 12.913085 | C20: =2*PI()*B20 -> 81.135303 | D20: =SQRT(L_Rp0^2+L_Rp1^2*C20) -> 76746434 | E20: =COMPLEX(D20,C20*L_Mp) -> 76746433.8394877+1198589.05027705i | F20: =IMDIV(1,E20) -> 1.30267440777974e-08-2.03445450573832e-10i | G20: =COMPLEX(0,C20*L_Cf) -> 8.57939127712575e-14i | H20: =COMPLEX(0,C20*L_Cbv) -> 8.57939127712575e-13i | I20: =COMPLEX(L_Rsq+L_Rh,C20*(L_Md+L_Mh)-1/(C20*L_Cd)) -> 552400610.124532-14198236923781.3i | J20: =IMDIV(1,I20) -> 2.74021923867872e-18+7.04312798733027e-14i | K20: =IMSUM(F20,G20,H20) -> 1.30267440777974e-08-2.02501717533348e-10i | L20: =IMSUM(IMPRODUCT(IMSUM(F20,G20),H20),IMPRODUCT(IMSUM(J20,L_Yv),K20)) -> 2.62422565133197e-20+1.16886397190559e-20i | M20: =IMABS(IMDIV(IMPRODUCT(J20,F20,H20),L20))^2 -> 7.5096604e-28 | N20: =IMDIV(IMPRODUCT(L_Yv,K20,E20),H20) -> 0.000168842154446925-2.33116508281444i | O20: =IMABS(IMSUM(1,IMPRODUCT(E20,G20),N20))^2 -> 6.4346375 | P20: =IMABS(N20)^2 -> 5.4343307 | Q20: =p_Rb^2/(1+(C20*p_Rb*L_Ctot)^2) -> 2.5040435e+19 | R20: =M20*L_Kt^2*Q20 -> 3.77398e-06 | S20: =L_kT4*D20 -> 1.2636776e-12 | T20: =L_kT4*L_Rsq*O20 -> 3.3238064e-11 | U20: =L_kT4*L_Rh*O20 -> 2.5288943e-11 | V20: =L_kT4*p_Rv*P20 -> 4.4739812e-08 | W20: =L_kT4/p_Rb*Q20/R20 -> 1.0924973e-07 | X20: =p_en^2*(1+p_fc/B20)/R20 -> 1.4828412e-10 | Y20: =p_in^2*Q20/R20 -> 1.6587552e-08 | Z20: =p_eo^2/L_G^2/R20 -> 1.6798109e-11 | AA20: =SUM(S20:Z20) -> 1.7080196e-07 | AB20: =10*LOG10(AA20/L_PREF^2) -> 26.304329 | AC20: =10*LOG10(S20/L_PREF^2) -> -25.004237 | AD20: =10*LOG10(T20/L_PREF^2) -> -10.804243 | AE20: =10*LOG10(U20/L_PREF^2) -> -11.991293 | AF20: =10*LOG10(V20/L_PREF^2) -> 20.486342 | AG20: =10*LOG10(W20/L_PREF^2) -> 24.363604 | AH20: =10*LOG10(X20/L_PREF^2) -> -4.3096533 | AI20: =10*LOG10(Y20/L_PREF^2) -> 16.177223 | AJ20: =10*LOG10(Z20/L_PREF^2) -> -13.767996 | AK20: =10*LOG10(R20/$R$6) -> -7.5197131 | AL20: =(12194^2*B20^4/((B20^2+20.6^2)*SQRT((B20^2+107.7^2)*(B20^2+737.9^2))*(B20^2+12194^2))*1.2589254)^2 -> 5.472017e-07 | AM20: 0 | AN20: 0 | AO20: 0 | AP20: 0 | AQ20: 0 | AR20: 0 | AS20: 0 | AT20: 0 | AU20: 0 | AV20: 0 | AW20: 0 | AX20: 0 | AY20: 0 | AZ20: 0 | BA20: 0 | BB20: 0 | BC20: 0 | BD20: 0 | BE20: =IF(B20>2000,AK20,-999) -> -999 | BF20: =IF(AND(B20<1000,AK20>=-3),B20,1000000000) -> 1000000000
... A39: 0 | B39: =20*10^(A39/100) -> 20 | C39: =2*PI()*B39 -> 125.66371 | D39: =SQRT(L_Rp0^2+L_Rp1^2*C39) -> 76800045 | E39: =COMPLEX(D39,C39*L_Mp) -> 76800045.113452+1856394.64031562i | F39: =IMDIV(1,E39) -> 1.30132223779467e-08-3.14552891732927e-10i | G39: =COMPLEX(0,C39*L_Cf) -> 1.32879037901651e-13i | H39: =COMPLEX(0,C39*L_Cbv) -> 1.32879037901651e-12i | I39: =COMPLEX(L_Rsq+L_Rh,C39*(L_Md+L_Mh)-1/(C39*L_Cd)) -> 552400610.124532-9167151438563.27i | J39: =IMDIV(1,I39) -> 6.57332849712834e-18+1.09085139813684e-13i | K39: =IMSUM(F39,G39,H39) -> 1.30132223779467e-08-3.13091222316009e-10i | L39: =IMSUM(IMPRODUCT(IMSUM(F39,G39),H39),IMPRODUCT(IMSUM(J39,L_Yv),K39)) -> 2.64784821836791e-20+1.80852093756593e-20i | M39: =IMABS(IMDIV(IMPRODUCT(J39,F39,H39),L39))^2 -> 3.4625522e-27 | N39: =IMDIV(IMPRODUCT(L_Yv,K39,E39),H39) -> 0.000168960099249528-1.50512421275185i | O39: =IMABS(IMSUM(1,IMPRODUCT(E39,G39),N39))^2 -> 3.2657056 | P39: =IMABS(N39)^2 -> 2.2653989 | Q39: =p_Rb^2/(1+(C39*p_Rb*L_Ctot)^2) -> 1.0438743e+19 | R39: =M39*L_Kt^2*Q39 -> 7.2540737e-06 | S39: =L_kT4*D39 -> 1.2645604e-12 | T39: =L_kT4*L_Rsq*O39 -> 1.6868974e-11 | U39: =L_kT4*L_Rh*O39 -> 1.2834638e-11 | V39: =L_kT4*p_Rv*P39 -> 1.8650599e-08 | W39: =L_kT4/p_Rb*Q39/R39 -> 2.3694325e-08 | X39: =p_en^2*(1+p_fc/B39)/R39 -> 5.2935773e-11 | Y39: =p_in^2*Q39/R39 -> 3.5975452e-09 | Z39: =p_eo^2/L_G^2/R39 -> 8.7393277e-12 | AA39: =SUM(S39:Z39) -> 4.6035112e-08 | AB39: =10*LOG10(AA39/L_PREF^2) -> 20.610292 | AC39: =10*LOG10(S39/L_PREF^2) -> -25.001204 | AD39: =10*LOG10(T39/L_PREF^2) -> -13.749713 | AE39: =10*LOG10(U39/L_PREF^2) -> -14.936764 | AF39: =10*LOG10(V39/L_PREF^2) -> 16.686328 | AG39: =10*LOG10(W39/L_PREF^2) -> 17.725843 | AH39: =10*LOG10(X39/L_PREF^2) -> -8.7831073 | AI39: =10*LOG10(Y39/L_PREF^2) -> 9.5394627 | AJ39: =10*LOG10(Z39/L_PREF^2) -> -16.60582 | AK39: =10*LOG10(R39/$R$6) -> -4.6818894 | AL39: =(12194^2*B39^4/((B39^2+20.6^2)*SQRT((B39^2+107.7^2)*(B39^2+737.9^2))*(B39^2+12194^2))*1.2589254)^2 -> 9.1313356e-06 | AM39: 0 | AN39: 0 | AO39: 0 | AP39: 0 | AQ39: 0 | AR39: 0 | AS39: 0 | AT39: 0 | AU39: 0 | AV39: 0 | AW39: 0 | AX39: 0 | AY39: 0 | AZ39: 0 | BA39: 0 | BB39: 0 | BC39: 0 | BD39: 0 | BE39: =IF(B39>2000,AK39,-999) -> -999 | BF39: =IF(AND(B39<1000,AK39>=-3),B39,1000000000) -> 1000000000
A40: 1 | B40: =20*10^(A40/100) -> 20.46586 | C40: =2*PI()*B40 -> 128.59079 | D40: =SQRT(L_Rp0^2+L_Rp1^2*C40) -> 76803568 | E40: =COMPLEX(D40,C40*L_Mp) -> 76803567.9507591+1899635.62634253i | F40: =IMDIV(1,E40) -> 1.30122681181267e-08-3.2184140341712e-10i | G40: =COMPLEX(0,C40*L_Cf) -> 1.35974188305769e-13i | H40: =COMPLEX(0,C40*L_Cbv) -> 1.35974188305769e-12i | I40: =COMPLEX(L_Rsq+L_Rh,C40*(L_Md+L_Mh)-1/(C40*L_Cd)) -> 552400610.124532-8958481574095.24i | J40: =IMDIV(1,I40) -> 6.88311995739248e-18+1.11626059385935e-13i | K40: =IMSUM(F40,G40,H40) -> 1.30122681181267e-08-3.20345687345757e-10i | L40: =IMSUM(IMPRODUCT(IMSUM(F40,G40),H40),IMPRODUCT(IMSUM(J40,L_Yv),K40)) -> 2.6497821074105e-20+1.85051405878236e-20i | M40: =IMABS(IMDIV(IMPRODUCT(J40,F40,H40),L40))^2 -> 3.7365967e-27 | N40: =IMDIV(IMPRODUCT(L_Yv,K40,E40),H40) -> 0.000168967849491775-1.47086321476801i | O40: =IMABS(IMSUM(1,IMPRODUCT(E40,G40),N40))^2 -> 3.1637453 | P40: =IMABS(N40)^2 -> 2.1634386 | Q40: =p_Rb^2/(1+(C40*p_Rb*L_Ctot)^2) -> 9.968927e+18 | R40: =M40*L_Kt^2*Q40 -> 7.4758756e-06 | S40: =L_kT4*D40 -> 1.2646184e-12 | T40: =L_kT4*L_Rsq*O40 -> 1.6342299e-11 | U40: =L_kT4*L_Rh*O40 -> 1.2433921e-11 | V40: =L_kT4*p_Rv*P40 -> 1.7811179e-08 | W40: =L_kT4/p_Rb*Q40/R40 -> 2.1956567e-08 | X40: =p_en^2*(1+p_fc/B40)/R40 -> 5.0390875e-11 | Y40: =p_in^2*Q40/R40 -> 3.3336988e-09 | Z40: =p_eo^2/L_G^2/R40 -> 8.4800405e-12 | AA40: =SUM(S40:Z40) -> 4.3190357e-08 | AB40: =10*LOG10(AA40/L_PREF^2) -> 20.333268 | AC40: =10*LOG10(S40/L_PREF^2) -> -25.001005 | AD40: =10*LOG10(T40/L_PREF^2) -> -13.887468 | AE40: =10*LOG10(U40/L_PREF^2) -> -15.074519 | AF40: =10*LOG10(V40/L_PREF^2) -> 16.486327 | AG40: =10*LOG10(W40/L_PREF^2) -> 17.395044 | AH40: =10*LOG10(X40/L_PREF^2) -> -8.9970809 | AI40: =10*LOG10(Y40/L_PREF^2) -> 9.2086637 | AJ40: =10*LOG10(Z40/L_PREF^2) -> -16.736621 | AK40: =10*LOG10(R40/$R$6) -> -4.5510884 | AL40: =(12194^2*B40^4/((B40^2+20.6^2)*SQRT((B40^2+107.7^2)*(B40^2+737.9^2))*(B40^2+12194^2))*1.2589254)^2 -> 1.0476067e-05 | AM40: =0.5*(B40-B39)*(S40*AL40+S39*AL39) -> 5.7755794e-18 | AN40: =0.5*(B40-B39)*(T40*AL40+T39*AL39) -> 7.5757962e-17 | AO40: =0.5*(B40-B39)*(U40*AL40+U39*AL39) -> 5.7639903e-17 | AP40: =0.5*(B40-B39)*(V40*AL40+V39*AL39) -> 8.3131754e-14 | AQ40: =0.5*(B40-B39)*(W40*AL40+W39*AL39) -> 1.039751e-13 | AR40: =0.5*(B40-B39)*(X40*AL40+X39*AL39) -> 2.3555562e-16 | AS40: =0.5*(B40-B39)*(Y40*AL40+Y39*AL39) -> 1.5786696e-14 | AT40: =0.5*(B40-B39)*(Z40*AL40+Z39*AL39) -> 3.9281118e-17 | AU40: =0.5*(B40-B39)*(AA40*AL40+AA39*AL39) -> 2.0330756e-13 | AV40: =0.5*(B40-B39)*(S40+S39) -> 5.891214e-13 | AW40: =0.5*(B40-B39)*(T40+T39) -> 7.7358994e-12 | AX40: =0.5*(B40-B39)*(U40+U39) -> 5.8858037e-12 | AY40: =0.5*(B40-B39)*(V40+V39) -> 8.4930391e-09 | AZ40: =0.5*(B40-B39)*(W40+W39) -> 1.0633459e-08 | BA40: =0.5*(B40-B39)*(X40+X39) -> 2.4067868e-11 | BB40: =0.5*(B40-B39)*(Y40+Y39) -> 1.6144941e-09 | BC40: =0.5*(B40-B39)*(Z40+Z39) -> 4.0109061e-12 | BD40: =0.5*(B40-B39)*(AA40+AA39) -> 2.0783282e-08 | BE40: =IF(B40>2000,AK40,-999) -> -999 | BF40: =IF(AND(B40<1000,AK40>=-3),B40,1000000000) -> 1000000000
A41: 2 | B41: =20*10^(A41/100) -> 20.942571 | C41: =2*PI()*B41 -> 131.58605 | D41: =SQRT(L_Rp0^2+L_Rp1^2*C41) -> 76807173 | E41: =COMPLEX(D41,C41*L_Mp) -> 76807172.6782208+1943883.82432317i | F41: =IMDIV(1,E41) -> 1.30112833051271e-08-3.29297671930768e-10i | G41: =COMPLEX(0,C41*L_Cf) -> 1.39141434024357e-13i | H41: =COMPLEX(0,C41*L_Cbv) -> 1.39141434024357e-12i | I41: =COMPLEX(L_Rsq+L_Rh,C41*(L_Md+L_Mh)-1/(C41*L_Cd)) -> 552400610.124532-8754561615137.32i | J41: =IMDIV(1,I41) -> 7.20751144249686e-18+1.14226164596236e-13i | K41: =IMSUM(F41,G41,H41) -> 1.30112833051271e-08-3.277671161565e-10i | L41: =IMSUM(IMPRODUCT(IMSUM(F41,G41),H41),IMPRODUCT(IMSUM(J41,L_Yv),K41)) -> 2.65180958693335e-20+1.89347785694471e-20i | M41: =IMABS(IMDIV(IMPRODUCT(J41,F41,H41),L41))^2 -> 4.0303825e-27 | N41: =IMDIV(IMPRODUCT(L_Yv,K41,E41),H41) -> 0.000168975779892202-1.43738208792981i | O41: =IMABS(IMSUM(1,IMPRODUCT(E41,G41),N41))^2 -> 3.066374 | P41: =IMABS(N41)^2 -> 2.0660673 | Q41: =p_Rb^2/(1+(C41*p_Rb*L_Ctot)^2) -> 9.5202557e+18 | R41: =M41*L_Kt^2*Q41 -> 7.7007371e-06 | S41: =L_kT4*D41 -> 1.2646777e-12 | T41: =L_kT4*L_Rsq*O41 -> 1.5839328e-11 | U41: =L_kT4*L_Rh*O41 -> 1.205124e-11 | V41: =L_kT4*p_Rv*P41 -> 1.7009539e-08 | W41: =L_kT4/p_Rb*Q41/R41 -> 2.0356092e-08 | X41: =p_en^2*(1+p_fc/B41)/R41 -> 4.7995097e-11 | Y41: =p_in^2*Q41/R41 -> 3.0906962e-09 | Z41: =p_eo^2/L_G^2/R41 -> 8.2324233e-12 | AA41: =SUM(S41:Z41) -> 4.054171e-08 | AB41: =10*LOG10(AA41/L_PREF^2) -> 20.058421 | AC41: =10*LOG10(S41/L_PREF^2) -> -25.000801 | AD41: =10*LOG10(T41/L_PREF^2) -> -14.023232 | AE41: =10*LOG10(U41/L_PREF^2) -> -15.210283 | AF41: =10*LOG10(V41/L_PREF^2) -> 16.286326 | AG41: =10*LOG10(W41/L_PREF^2) -> 17.066344 | AH41: =10*LOG10(X41/L_PREF^2) -> -9.2086311 | AI41: =10*LOG10(Y41/L_PREF^2) -> 8.8799633 | AJ41: =10*LOG10(Z41/L_PREF^2) -> -16.865323 | AK41: =10*LOG10(R41/$R$6) -> -4.4223861 | AL41: =(12194^2*B41^4/((B41^2+20.6^2)*SQRT((B41^2+107.7^2)*(B41^2+737.9^2))*(B41^2+12194^2))*1.2589254)^2 -> 1.2005219e-05 | AM41: =0.5*(B41-B40)*(S41*AL41+S40*AL40) -> 6.7766772e-18 | AN41: =0.5*(B41-B40)*(T41*AL41+T40*AL40) -> 8.6131599e-17 | AO41: =0.5*(B41-B40)*(U41*AL41+U40*AL40) -> 6.553261e-17 | AP41: =0.5*(B41-B40)*(V41*AL41+V40*AL40) -> 9.3148006e-14 | AQ41: =0.5*(B41-B40)*(W41*AL41+W40*AL40) -> 1.1307535e-13 | AR41: =0.5*(B41-B40)*(X41*AL41+X40*AL40) -> 2.6316595e-16 | AS41: =0.5*(B41-B40)*(Y41*AL41+Y40*AL40) -> 1.7168402e-14 | AT41: =0.5*(B41-B40)*(Z41*AL41+Z40*AL40) -> 4.4732072e-17 | AU41: =0.5*(B41-B40)*(AA41*AL41+AA40*AL40) -> 2.238581e-13 | AV41: =0.5*(B41-B40)*(S41+S40) -> 6.0287178e-13 | AW41: =0.5*(B41-B40)*(T41+T40) -> 7.6706698e-12 | AX41: =0.5*(B41-B40)*(U41+U40) -> 5.8361742e-12 | AY41: =0.5*(B41-B40)*(V41+V40) -> 8.2997118e-09 | AZ41: =0.5*(B41-B40)*(W41+W40) -> 1.0085457e-08 | BA41: =0.5*(B41-B40)*(X41+X40) -> 2.3450843e-11 | BB41: =0.5*(B41-B40)*(Y41+Y40) -> 1.5312903e-09 | BC41: =0.5*(B41-B40)*(Z41+Z40) -> 3.9835086e-12 | BD41: =0.5*(B41-B40)*(AA41+AA40) -> 1.9958004e-08 | BE41: =IF(B41>2000,AK41,-999) -> -999 | BF41: =IF(AND(B41<1000,AK41>=-3),B41,1000000000) -> 1000000000
A42: 3 | B42: =20*10^(A42/100) -> 21.430386 | C42: =2*PI()*B42 -> 134.65109 | D42: =SQRT(L_Rp0^2+L_Rp1^2*C42) -> 76810861 | E42: =COMPLEX(D42,C42*L_Mp) -> 76810861.1954452+1989162.69523781i | F42: =IMDIV(1,E42) -> 1.30102668401394e-08-3.36925495310415e-10i | G42: =COMPLEX(0,C42*L_Cf) -> 1.42382454373019e-13i | H42: =COMPLEX(0,C42*L_Cbv) -> 1.42382454373019e-12i | I42: =COMPLEX(L_Rsq+L_Rh,C42*(L_Md+L_Mh)-1/(C42*L_Cd)) -> 552400610.124532-8555283440628.06i | J42: =IMDIV(1,I42) -> 7.54719103071468e-18+1.1688683405649e-13i | K42: =IMSUM(F42,G42,H42) -> 1.30102668401394e-08-3.35359288312312e-10i | L42: =IMSUM(IMPRODUCT(IMSUM(F42,G42),H42),IMPRODUCT(IMSUM(J42,L_Yv),K42)) -> 2.65393510187286e-20+1.93743450409983e-20i | M42: =IMABS(IMDIV(IMPRODUCT(J42,F42,H42),L42))^2 -> 4.3451387e-27 | N42: =IMDIV(IMPRODUCT(L_Yv,K42,E42),H42) -> 0.000168983894629806-1.40466308010063i | O42: =IMABS(IMSUM(1,IMPRODUCT(E42,G42),N42))^2 -> 2.9733851 | P42: =IMABS(N42)^2 -> 1.9730784 | Q42: =p_Rb^2/(1+(C42*p_Rb*L_Ctot)^2) -> 9.0917775e+18 | R42: =M42*L_Kt^2*Q42 -> 7.9284788e-06 | S42: =L_kT4*D42 -> 1.2647385e-12 | T42: =L_kT4*L_Rsq*O42 -> 1.5358995e-11 | U42: =L_kT4*L_Rh*O42 -> 1.1685781e-11 | V42: =L_kT4*p_Rv*P42 -> 1.624398e-08 | W42: =L_kT4/p_Rb*Q42/R42 -> 1.8881523e-08 | X42: =p_en^2*(1+p_fc/B42)/R42 -> 4.5739086e-11 | Y42: =p_in^2*Q42/R42 -> 2.8668102e-09 | Z42: =p_eo^2/L_G^2/R42 -> 7.9959509e-12 | AA42: =SUM(S42:Z42) -> 3.8074357e-08 | AB42: =10*LOG10(AA42/L_PREF^2) -> 19.785726 | AC42: =10*LOG10(S42/L_PREF^2) -> -25.000593 | AD42: =10*LOG10(T42/L_PREF^2) -> -14.156972 | AE42: =10*LOG10(U42/L_PREF^2) -> -15.344022 | AF42: =10*LOG10(V42/L_PREF^2) -> 16.086324 | AG42: =10*LOG10(W42/L_PREF^2) -> 16.73977 | AH42: =10*LOG10(X42/L_PREF^2) -> -9.4177251 | AI42: =10*LOG10(Y42/L_PREF^2) -> 8.5533895 | AJ42: =10*LOG10(Z42/L_PREF^2) -> -16.991899 | AK42: =10*LOG10(R42/$R$6) -> -4.2958103 | AL42: =(12194^2*B42^4/((B42^2+20.6^2)*SQRT((B42^2+107.7^2)*(B42^2+737.9^2))*(B42^2+12194^2))*1.2589254)^2 -> 1.3741953e-05 | AM42: =0.5*(B42-B41)*(S42*AL42+S41*AL41) -> 7.9422913e-18 | AN42: =0.5*(B42-B41)*(T42*AL42+T41*AL41) -> 9.7859911e-17 | AO42: =0.5*(B42-B41)*(U42*AL42+U41*AL41) -> 7.4456013e-17 | AP42: =0.5*(B42-B41)*(V42*AL42+V41*AL41) -> 1.0425274e-13 | AQ42: =0.5*(B42-B41)*(W42*AL42+W41*AL41) -> 1.2289242e-13 | AR42: =0.5*(B42-B41)*(X42*AL42+X41*AL41) -> 2.9384424e-16 | AS42: =0.5*(B42-B41)*(Y42*AL42+Y41*AL41) -> 1.8658943e-14 | AT42: =0.5*(B42-B41)*(Z42*AL42+Z41*AL41) -> 5.0906443e-17 | AU42: =0.5*(B42-B41)*(AA42*AL42+AA41*AL41) -> 2.4632912e-13 | AV42: =0.5*(B42-B41)*(S42+S41) -> 6.1694376e-13 | AW42: =0.5*(B42-B41)*(T42+T41) -> 7.6095073e-12 | AX42: =0.5*(B42-B41)*(U42+U41) -> 5.7896391e-12 | AY42: =0.5*(B42-B41)*(V42+V41) -> 8.1107851e-09 | AZ42: =0.5*(B42-B41)*(W42+W41) -> 9.5703513e-09 | BA42: =0.5*(B42-B41)*(X42+X41) -> 2.2862477e-11 | BB42: =0.5*(B42-B41)*(Y42+Y41) -> 1.4530809e-09 | BC42: =0.5*(B42-B41)*(Z42+Z41) -> 3.9582234e-12 | BD42: =0.5*(B42-B41)*(AA42+AA41) -> 1.9175054e-08 | BE42: =IF(B42>2000,AK42,-999) -> -999 | BF42: =IF(AND(B42<1000,AK42>=-3),B42,1000000000) -> 1000000000
A43: 4 | B43: =20*10^(A43/100) -> 21.929564 | C43: =2*PI()*B43 -> 137.78751 | D43: =SQRT(L_Rp0^2+L_Rp1^2*C43) -> 76814635 | E43: =COMPLEX(D43,C43*L_Mp) -> 76814635.4459196+2035496.24654315i | F43: =IMDIV(1,E43) -> 1.30092175809252e-08-3.44728753872424e-10i | G43: =COMPLEX(0,C43*L_Cf) -> 1.45698967783645e-13i | H43: =COMPLEX(0,C43*L_Cbv) -> 1.45698967783645e-12i | I43: =COMPLEX(L_Rsq+L_Rh,C43*(L_Md+L_Mh)-1/(C43*L_Cd)) -> 552400610.124532-8360541390641.59i | J43: =IMDIV(1,I43) -> 7.90287922847808e-18+1.19609478490687e-13i | K43: =IMSUM(F43,G43,H43) -> 1.30092175809252e-08-3.43126065226804e-10i | L43: =IMSUM(IMPRODUCT(IMSUM(F43,G43),H43),IMPRODUCT(IMSUM(J43,L_Yv),K43)) -> 2.65616330559976e-20+1.98240666204254e-20i | M43: =IMABS(IMDIV(IMPRODUCT(J43,F43,H43),L43))^2 -> 4.6821548e-27 | N43: =IMDIV(IMPRODUCT(L_Yv,K43,E43),H43) -> 0.000168992197981027-1.37268884322945i | O43: =IMABS(IMSUM(1,IMPRODUCT(E43,G43),N43))^2 -> 2.8845814 | P43: =IMABS(N43)^2 -> 1.8842747 | Q43: =p_Rb^2/(1+(C43*p_Rb*L_Ctot)^2) -> 8.6825836e+18 | R43: =M43*L_Kt^2*Q43 -> 8.1589105e-06 | S43: =L_kT4*D43 -> 1.2648006e-12 | T43: =L_kT4*L_Rsq*O43 -> 1.490028e-11 | U43: =L_kT4*L_Rh*O43 -> 1.1336771e-11 | V43: =L_kT4*p_Rv*P43 -> 1.5512875e-08 | W43: =L_kT4/p_Rb*Q43/R43 -> 1.7522453e-08 | X43: =p_en^2*(1+p_fc/B43)/R43 -> 4.3614092e-11 | Y43: =p_in^2*Q43/R43 -> 2.6604605e-09 | Z43: =p_eo^2/L_G^2/R43 -> 7.7701218e-12 | AA43: =SUM(S43:Z43) -> 3.5774675e-08 | AB43: =10*LOG10(AA43/L_PREF^2) -> 19.515157 | AC43: =10*LOG10(S43/L_PREF^2) -> -25.000379 | AD43: =10*LOG10(T43/L_PREF^2) -> -14.288656 | AE43: =10*LOG10(U43/L_PREF^2) -> -15.475706 | AF43: =10*LOG10(V43/L_PREF^2) -> 15.886323 | AG43: =10*LOG10(W43/L_PREF^2) -> 16.415349 | AH43: =10*LOG10(X43/L_PREF^2) -> -9.6243316 | AI43: =10*LOG10(Y43/L_PREF^2) -> 8.2289683 | AJ43: =10*LOG10(Z43/L_PREF^2) -> -17.116322 | AK43: =10*LOG10(R43/$R$6) -> -4.1713874 | AL43: =(12194^2*B43^4/((B43^2+20.6^2)*SQRT((B43^2+107.7^2)*(B43^2+737.9^2))*(B43^2+12194^2))*1.2589254)^2 -> 1.5712039e-05 | AM43: =0.5*(B43-B42)*(S43*AL43+S42*AL42) -> 9.297829e-18 | AN43: =0.5*(B43-B42)*(T43*AL43+T42*AL42) -> 1.1111108e-16 | AO43: =0.5*(B43-B42)*(U43*AL43+U42*AL42) -> 8.4538073e-17 | AP43: =0.5*(B43-B42)*(V43*AL43+V42*AL42) -> 1.1654876e-13 | AQ43: =0.5*(B43-B42)*(W43*AL43+W42*AL42) -> 1.3347577e-13 | AR43: =0.5*(B43-B42)*(X43*AL43+X42*AL42) -> 3.2791257e-16 | AS43: =0.5*(B43-B42)*(Y43*AL43+Y42*AL42) -> 2.0265828e-14 | AT43: =0.5*(B43-B42)*(Z43*AL43+Z42*AL42) -> 5.7895751e-17 | AU43: =0.5*(B43-B42)*(AA43*AL43+AA42*AL42) -> 2.7088112e-13 | AV43: =0.5*(B43-B42)*(S43+S42) -> 6.3134489e-13 | AW43: =0.5*(B43-B42)*(T43+T42) -> 7.5523795e-12 | AX43: =0.5*(B43-B42)*(U43+U42) -> 5.7461738e-12 | AY43: =0.5*(B43-B42)*(V43+V42) -> 7.9261588e-09 | AZ43: =0.5*(B43-B42)*(W43+W42) -> 9.0860285e-09 | BA43: =0.5*(B43-B42)*(X43+X42) -> 2.2301562e-11 | BB43: =0.5*(B43-B42)*(Y43+Y42) -> 1.3795455e-09 | BC43: =0.5*(B43-B42)*(Z43+Z42) -> 3.9350369e-12 | BD43: =0.5*(B43-B42)*(AA43+AA42) -> 1.8431899e-08 | BE43: =IF(B43>2000,AK43,-999) -> -999 | BF43: =IF(AND(B43<1000,AK43>=-3),B43,1000000000) -> 1000000000
A44: 5 | B44: =20*10^(A44/100) -> 22.440369 | C44: =2*PI()*B44 -> 140.997 | D44: =SQRT(L_Rp0^2+L_Rp1^2*C44) -> 76818497 | E44: =COMPLEX(D44,C44*L_Mp) -> 76818497.4180152+2082909.04490138i | F44: =IMDIV(1,E44) -> 1.30081343399962e-08-3.52711411766252e-10i | G44: =COMPLEX(0,C44*L_Cf) -> 1.49092732715543e-13i | H44: =COMPLEX(0,C44*L_Cbv) -> 1.49092732715543e-12i | I44: =COMPLEX(L_Rsq+L_Rh,C44*(L_Md+L_Mh)-1/(C44*L_Cd)) -> 552400610.124532-8170232210365.29i | J44: =IMDIV(1,I44) -> 8.2753304986731e-18+1.22395541482901e-13i | K44: =IMSUM(F44,G44,H44) -> 1.30081343399962e-08-3.51071391706381e-10i | L44: =IMSUM(IMPRODUCT(IMSUM(F44,G44),H44),IMPRODUCT(IMSUM(J44,L_Yv),K44)) -> 2.65849906956627e-20+2.02841749203909e-20i | M44: =IMABS(IMDIV(IMPRODUCT(J44,F44,H44),L44))^2 -> 5.0427819e-27 | N44: =IMDIV(IMPRODUCT(L_Yv,K44,E44),H44) -> 0.000169000694319643-1.34144242415262i | O44: =IMABS(IMSUM(1,IMPRODUCT(E44,G44),N44))^2 -> 2.7997745 | P44: =IMABS(N44)^2 -> 1.7994678 | Q44: =p_Rb^2/(1+(C44*p_Rb*L_Ctot)^2) -> 8.2918063e+18 | R44: =M44*L_Kt^2*Q44 -> 8.3918315e-06 | S44: =L_kT4*D44 -> 1.2648642e-12 | T44: =L_kT4*L_Rsq*O44 -> 1.4462211e-11 | U44: =L_kT4*L_Rh*O44 -> 1.100347e-11 | V44: =L_kT4*p_Rv*P44 -> 1.4814677e-08 | W44: =L_kT4/p_Rb*Q44/R44 -> 1.626936e-08 | X44: =p_en^2*(1+p_fc/B44)/R44 -> 4.161193e-11 | Y44: =p_in^2*Q44/R44 -> 2.4702016e-09 | Z44: =p_eo^2/L_G^2/R44 -> 7.5544567e-12 | AA44: =SUM(S44:Z44) -> 3.3630135e-08 | AB44: =10*LOG10(AA44/L_PREF^2) -> 19.246686 | AC44: =10*LOG10(S44/L_PREF^2) -> -25.000161 | AD44: =10*LOG10(T44/L_PREF^2) -> -14.418253 | AE44: =10*LOG10(U44/L_PREF^2) -> -15.605303 | AF44: =10*LOG10(V44/L_PREF^2) -> 15.686322 | AG44: =10*LOG10(W44/L_PREF^2) -> 16.093105 | AH44: =10*LOG10(X44/L_PREF^2) -> -9.8284214 | AI44: =10*LOG10(Y44/L_PREF^2) -> 7.9067241 | AJ44: =10*LOG10(Z44/L_PREF^2) -> -17.238568 | AK44: =10*LOG10(R44/$R$6) -> -4.0491415 | AL44: =(12194^2*B44^4/((B44^2+20.6^2)*SQRT((B44^2+107.7^2)*(B44^2+737.9^2))*(B44^2+12194^2))*1.2589254)^2 -> 1.794411e-05 | AM44: =0.5*(B44-B43)*(S44*AL44+S43*AL43) -> 1.087235e-17 | AN44: =0.5*(B44-B43)*(T44*AL44+T43*AL43) -> 1.2607317e-16 | AO44: =0.5*(B44-B43)*(U44*AL44+U43*AL43) -> 9.5921871e-17 | AP44: =0.5*(B44-B43)*(V44*AL44+V43*AL43) -> 1.3014679e-13 | AQ44: =0.5*(B44-B43)*(W44*AL44+W43*AL43) -> 1.4487779e-13 | AR44: =0.5*(B44-B43)*(X44*AL44+X43*AL43) -> 3.657251e-16 | AS44: =0.5*(B44-B43)*(Y44*AL44+Y43*AL43) -> 2.1997015e-14 | AT44: =0.5*(B44-B43)*(Z44*AL44+Z43*AL43) -> 6.5802549e-17 | AU44: =0.5*(B44-B43)*(AA44*AL44+AA43*AL43) -> 2.97686e-13 | AV44: =0.5*(B44-B43)*(S44+S43) -> 6.4608292e-13 | AW44: =0.5*(B44-B43)*(T44+T43) -> 7.499256e-12 | AX44: =0.5*(B44-B43)*(U44+U43) -> 5.7057552e-12 | AY44: =0.5*(B44-B43)*(V44+V43) -> 7.7457351e-09 | AZ44: =0.5*(B44-B43)*(W44+W43) -> 8.6305163e-09 | BA44: =0.5*(B44-B43)*(X44+X43) -> 2.1766946e-11 | BB44: =0.5*(B44-B43)*(Y44+Y43) -> 1.3103844e-09 | BC44: =0.5*(B44-B43)*(Z44+Z43) -> 3.9139369e-12 | BD44: =0.5*(B44-B43)*(AA44+AA43) -> 1.7726168e-08 | BE44: =IF(B44>2000,AK44,-999) -> -999 | BF44: =IF(AND(B44<1000,AK44>=-3),B44,1000000000) -> 1000000000
